Workbook

Sheet 24
B1: 证券代码 | C1: 发行人中文名称 | D1: 最新外评 | E1: 现金/存款 | F1: 不良生成率 | G1: 不良+关注 | H1: 关注类占比 | I1: 资产规模 | J1: 吸收存款 | K1: 不良贷款率 | L1: 拨备覆盖率 | M1: 资本充足率 | N1: 核心一级资本充足率 | O1: ROE(3年移动平均） | P1: 地产+建筑贷款/总贷款 | Q1: 对公活期存款/总存款 | R1: 同业资金/总负债 | S1: 对公活期存款+同业资金/总负债 | T1: 第一大股东 | U1: 第一大股东持股比例 | V1: 所在省 | W1: 所在地 | X1: 单一最大贷客户款占资本净额比例 | Y1: 最大十家客户贷款占资本净额比例 | Z1: 生息资产收益率 | AA1: 计息负债平均成本 | AB1: 净息差 | AC1: 成本收入比 | AD1: 非息收入占比
A2: 2024-06-30 | B2: 091506001.IB | C2: =IF([1]!b_info_issuer(B2)="0","",IFERROR([1]!b_info_issuer(B2),"")) -> 香港上海汇丰银行有限公司 | D2: =IF([1]!b_info_latestissurercreditrating(B2)="0","",IFERROR([1]!b_info_latestissurercreditrating(B2),"")) -> AAA | E2: =IFERROR(([1]!b_stm07_bs($B2,47,$A2,1,100000000))/[1]!b_stm07_bs($B2,109,$A2,1,100000000),"") | F2: =IFERROR(([1]!s_stmnote_bank_26($B2,$A2,1,100000000)-[1]!s_stmnote_bank_26($B2,#REF!,1,100000000)+#REF!)/[1]!s_stmnote_bank_1n($B2,#REF!,1,100000000),"") | G2: =IFERROR(H2+K2/100,"") | H2: =IFERROR([1]!s_stmnote_bank($B2,"34",$A2,100000000)/[1]!s_stmnote_bank_1n(B2,$A2,1,100000000),"") | I2: =[1]!b_stm07_bs(B2,74,$A2,1,100000000) -> 0 | J2: =[1]!b_stm07_bs(B2,109,$A2,1,100000000) -> 0 | K2: =[1]!s_stmnote_bank_5n(B2,$A2,1) -> 0 | L2: =[1]!s_stmnote_bank_23n(B2,$A2,1) -> 0 | M2: =[1]!s_stmnote_bank_capadequacyratio(B2,$A2,1) -> 0 | N2: =[1]!s_stmnote_bank_capadequacyratio_ct1(B2,$A2,1) -> 0 | O2: =IF(OR([1]!s_fa_roe(B2,20201231)="0",[1]!s_fa_roe(B2,20211231)="0",[1]!s_fa_roe(B2,20221231)="0"),"",IFERROR(([1]!s_fa_roe(B2,20221231)+[1]!s_fa_roe(B2,20201231)+[1]!s_fa_roe(B2,20211231))/3,"")) -> 0 | P2: =IFERROR(([1]!s_stmnote_bank_65(B2,$A2,1,2,4,100000000)+[1]!s_stmnote_bank_65(B2,$A2,1,2,6,100000000))/[1]!s_stmnote_bank_1n(B2,$A2,1,100000000),"") | Q2: =IFERROR([1]!s_stmnote_bank_614(B2,$A2,1,2,100000000)/[1]!s_stmnote_bank_647(B2,$A2,1,2,100000000),"") | R2: =IFERROR(([1]!b_stm07_bs(B2,104,$A2,1,100000000)+[1]!b_stm07_bs(B2,106,$A2,1,100000000)+[1]!b_stm07_bs(B2,76,$A2,1,100000000)+[1]!b_stm07_bs(B2,108,$A2,1,100000000)+[1]!b_stm07_bs(B2,95,$A2,1,100000000))/[1]!b_stm07_bs(B2,128,$A2,1,100000000),"") | S2: =IFERROR(([1]!s_stmnote_bank_614(B2,$A2,1,2,100000000)+[1]!b_stm07_bs(B2,104,$A2,1,100000000)+[1]!b_stm07_bs(B2,106,$A2,1,100000000)+[1]!b_stm07_bs(B2,76,$A2,1,100000000)+[1]!b_stm07_bs(B2,108,$A2,1,100000000)+[1]!b_stm07_bs(B2,95,$A2,1,100000000))/[1]!b_stm07_bs(B2,128,$A2,1,100000000),"") | T2: =[1]!b_issuer_shareholder(B2,"",1) -> 汇丰控股有限公司 | U2: =[1]!b_issuer_propofshareholder(B2,"",1) -> 100 | V2: =LEFT(C2,2) -> 香港 | W2: =[1]!s_info_city(B2) -> 香港特别行政区 | X2: =IF([1]!s_stmnote_bank_17n(B2,$A2,1)="0","",[1]!s_stmnote_bank_17n(B2,$A2,1)) -> 0 | Y2: =IF([1]!s_stmnote_bank_18n(B2,$A2,1)="0","",[1]!s_stmnote_bank_18n(B2,$A2,1)) -> 0 | Z2: =IF([1]!s_stmnote_bank_58(B2,$A2,1)="0","",[1]!s_stmnote_bank_58(B2,$A2,1)) -> 0 | AA2: =IF([1]!s_stmnote_bank_60(B2,$A2,1)="0","",[1]!s_stmnote_bank_60(B2,$A2,1)) -> 0 | AB2: =[1]!s_stmnote_bank_5444(B2,$A2,1) -> 0 | AC2: =[1]!s_stmnote_bank_129n($B2,$A2,1) -> 0 | AD2: =[1]!s_stmnote_bank_30(B2,$A2,1) -> 0
A3: 2024-06-30 | B3: 091506002.IB | C3: =IF([1]!b_info_issuer(B3)="0","",IFERROR([1]!b_info_issuer(B3),"")) -> 0 | D3: =IF([1]!b_info_latestissurercreditrating(B3)="0","",IFERROR([1]!b_info_latestissurercreditrating(B3),"")) -> 0 | E3: =IFERROR(([1]!b_stm07_bs($B3,47,$A3,1,100000000))/[1]!b_stm07_bs($B3,109,$A3,1,100000000),"") | F3: =IFERROR(([1]!s_stmnote_bank_26($B3,$A3,1,100000000)-[1]!s_stmnote_bank_26($B3,#REF!,1,100000000)+#REF!)/[1]!s_stmnote_bank_1n($B3,#REF!,1,100000000),"") | G3: =IFERROR(H3+K3/100,"") | H3: =IFERROR([1]!s_stmnote_bank($B3,"34",$A3,100000000)/[1]!s_stmnote_bank_1n(B3,$A3,1,100000000),"") | I3: =[1]!b_stm07_bs(B3,74,$A3,1,100000000) -> 0 | J3: =[1]!b_stm07_bs(B3,109,$A3,1,100000000) -> 0 | K3: =[1]!s_stmnote_bank_5n(B3,$A3,1) -> 0 | L3: =[1]!s_stmnote_bank_23n(B3,$A3,1) -> 0 | M3: =[1]!s_stmnote_bank_capadequacyratio(B3,$A3,1) -> 0 | N3: =[1]!s_stmnote_bank_capadequacyratio_ct1(B3,$A3,1) -> 0 | O3: =IF(OR([1]!s_fa_roe(B3,20201231)="0",[1]!s_fa_roe(B3,20211231)="0",[1]!s_fa_roe(B3,20221231)="0"),"",IFERROR(([1]!s_fa_roe(B3,20221231)+[1]!s_fa_roe(B3,20201231)+[1]!s_fa_roe(B3,20211231))/3,"")) -> 0 | P3: =IFERROR(([1]!s_stmnote_bank_65(B3,$A3,1,2,4,100000000)+[1]!s_stmnote_bank_65(B3,$A3,1,2,6,100000000))/[1]!s_stmnote_bank_1n(B3,$A3,1,100000000),"") | Q3: =IFERROR([1]!s_stmnote_bank_614(B3,$A3,1,2,100000000)/[1]!s_stmnote_bank_647(B3,$A3,1,2,100000000),"") | R3: =IFERROR(([1]!b_stm07_bs(B3,104,$A3,1,100000000)+[1]!b_stm07_bs(B3,106,$A3,1,100000000)+[1]!b_stm07_bs(B3,76,$A3,1,100000000)+[1]!b_stm07_bs(B3,108,$A3,1,100000000)+[1]!b_stm07_bs(B3,95,$A3,1,100000000))/[1]!b_stm07_bs(B3,128,$A3,1,100000000),"") | S3: =IFERROR(([1]!s_stmnote_bank_614(B3,$A3,1,2,100000000)+[1]!b_stm07_bs(B3,104,$A3,1,100000000)+[1]!b_stm07_bs(B3,106,$A3,1,100000000)+[1]!b_stm07_bs(B3,76,$A3,1,100000000)+[1]!b_stm07_bs(B3,108,$A3,1,100000000)+[1]!b_stm07_bs(B3,95,$A3,1,100000000))/[1]!b_stm07_bs(B3,128,$A3,1,100000000),"") | T3: =[1]!b_issuer_shareholder(B3,"",1) -> 0 | U3: =[1]!b_issuer_propofshareholder(B3,"",1) -> 0 | V3: =LEFT(C3,2) -> 0 | W3: =[1]!s_info_city(B3) -> 0 | X3: =IF([1]!s_stmnote_bank_17n(B3,$A3,1)="0","",[1]!s_stmnote_bank_17n(B3,$A3,1)) -> 0 | Y3: =IF([1]!s_stmnote_bank_18n(B3,$A3,1)="0","",[1]!s_stmnote_bank_18n(B3,$A3,1)) -> 0 | Z3: =IF([1]!s_stmnote_bank_58(B3,$A3,1)="0","",[1]!s_stmnote_bank_58(B3,$A3,1)) -> 0 | AA3: =IF([1]!s_stmnote_bank_60(B3,$A3,1)="0","",[1]!s_stmnote_bank_60(B3,$A3,1)) -> 0 | AB3: =[1]!s_stmnote_bank_5444(B3,$A3,1) -> 0 | AC3: =[1]!s_stmnote_bank_129n($B3,$A3,1) -> 0 | AD3: =[1]!s_stmnote_bank_30(B3,$A3,1) -> 0
A4: 2024-06-30 | B4: 091506003.IB | C4: =IF([1]!b_info_issuer(B4)="0","",IFERROR([1]!b_info_issuer(B4),"")) -> 0 | D4: =IF([1]!b_info_latestissurercreditrating(B4)="0","",IFERROR([1]!b_info_latestissurercreditrating(B4),"")) -> 0 | E4: =IFERROR(([1]!b_stm07_bs($B4,47,$A4,1,100000000))/[1]!b_stm07_bs($B4,109,$A4,1,100000000),"") | F4: =IFERROR(([1]!s_stmnote_bank_26($B4,$A4,1,100000000)-[1]!s_stmnote_bank_26($B4,#REF!,1,100000000)+#REF!)/[1]!s_stmnote_bank_1n($B4,#REF!,1,100000000),"") | G4: =IFERROR(H4+K4/100,"") | H4: =IFERROR([1]!s_stmnote_bank($B4,"34",$A4,100000000)/[1]!s_stmnote_bank_1n(B4,$A4,1,100000000),"") | I4: =[1]!b_stm07_bs(B4,74,$A4,1,100000000) -> 0 | J4: =[1]!b_stm07_bs(B4,109,$A4,1,100000000) -> 0 | K4: =[1]!s_stmnote_bank_5n(B4,$A4,1) -> 0 | L4: =[1]!s_stmnote_bank_23n(B4,$A4,1) -> 0 | M4: =[1]!s_stmnote_bank_capadequacyratio(B4,$A4,1) -> 0 | N4: =[1]!s_stmnote_bank_capadequacyratio_ct1(B4,$A4,1) -> 0 | O4: =IF(OR([1]!s_fa_roe(B4,20201231)="0",[1]!s_fa_roe(B4,20211231)="0",[1]!s_fa_roe(B4,20221231)="0"),"",IFERROR(([1]!s_fa_roe(B4,20221231)+[1]!s_fa_roe(B4,20201231)+[1]!s_fa_roe(B4,20211231))/3,"")) -> 0 | P4: =IFERROR(([1]!s_stmnote_bank_65(B4,$A4,1,2,4,100000000)+[1]!s_stmnote_bank_65(B4,$A4,1,2,6,100000000))/[1]!s_stmnote_bank_1n(B4,$A4,1,100000000),"") | Q4: =IFERROR([1]!s_stmnote_bank_614(B4,$A4,1,2,100000000)/[1]!s_stmnote_bank_647(B4,$A4,1,2,100000000),"") | R4: =IFERROR(([1]!b_stm07_bs(B4,104,$A4,1,100000000)+[1]!b_stm07_bs(B4,106,$A4,1,100000000)+[1]!b_stm07_bs(B4,76,$A4,1,100000000)+[1]!b_stm07_bs(B4,108,$A4,1,100000000)+[1]!b_stm07_bs(B4,95,$A4,1,100000000))/[1]!b_stm07_bs(B4,128,$A4,1,100000000),"") | S4: =IFERROR(([1]!s_stmnote_bank_614(B4,$A4,1,2,100000000)+[1]!b_stm07_bs(B4,104,$A4,1,100000000)+[1]!b_stm07_bs(B4,106,$A4,1,100000000)+[1]!b_stm07_bs(B4,76,$A4,1,100000000)+[1]!b_stm07_bs(B4,108,$A4,1,100000000)+[1]!b_stm07_bs(B4,95,$A4,1,100000000))/[1]!b_stm07_bs(B4,128,$A4,1,100000000),"") | T4: =[1]!b_issuer_shareholder(B4,"",1) -> 0 | U4: =[1]!b_issuer_propofshareholder(B4,"",1) -> 0 | V4: =LEFT(C4,2) -> 0 | W4: =[1]!s_info_city(B4) -> 0 | X4: =IF([1]!s_stmnote_bank_17n(B4,$A4,1)="0","",[1]!s_stmnote_bank_17n(B4,$A4,1)) -> 0 | Y4: =IF([1]!s_stmnote_bank_18n(B4,$A4,1)="0","",[1]!s_stmnote_bank_18n(B4,$A4,1)) -> 0 | Z4: =IF([1]!s_stmnote_bank_58(B4,$A4,1)="0","",[1]!s_stmnote_bank_58(B4,$A4,1)) -> 0 | AA4: =IF([1]!s_stmnote_bank_60(B4,$A4,1)="0","",[1]!s_stmnote_bank_60(B4,$A4,1)) -> 0 | AB4: =[1]!s_stmnote_bank_5444(B4,$A4,1) -> 0 | AC4: =[1]!s_stmnote_bank_129n($B4,$A4,1) -> 0 | AD4: =[1]!s_stmnote_bank_30(B4,$A4,1) -> 0
A5: 2024-06-30 | B5: 091506004.IB | C5: =IF([1]!b_info_issuer(B5)="0","",IFERROR([1]!b_info_issuer(B5),"")) -> 0 | D5: =IF([1]!b_info_latestissurercreditrating(B5)="0","",IFERROR([1]!b_info_latestissurercreditrating(B5),"")) -> 0 | E5: =IFERROR(([1]!b_stm07_bs($B5,47,$A5,1,100000000))/[1]!b_stm07_bs($B5,109,$A5,1,100000000),"") | F5: =IFERROR(([1]!s_stmnote_bank_26($B5,$A5,1,100000000)-[1]!s_stmnote_bank_26($B5,#REF!,1,100000000)+#REF!)/[1]!s_stmnote_bank_1n($B5,#REF!,1,100000000),"") | G5: =IFERROR(H5+K5/100,"") | H5: =IFERROR([1]!s_stmnote_bank($B5,"34",$A5,100000000)/[1]!s_stmnote_bank_1n(B5,$A5,1,100000000),"") | I5: =[1]!b_stm07_bs(B5,74,$A5,1,100000000) -> 0 | J5: =[1]!b_stm07_bs(B5,109,$A5,1,100000000) -> 0 | K5: =[1]!s_stmnote_bank_5n(B5,$A5,1) -> 0 | L5: =[1]!s_stmnote_bank_23n(B5,$A5,1) -> 0 | M5: =[1]!s_stmnote_bank_capadequacyratio(B5,$A5,1) -> 0 | N5: =[1]!s_stmnote_bank_capadequacyratio_ct1(B5,$A5,1) -> 0 | O5: =IF(OR([1]!s_fa_roe(B5,20201231)="0",[1]!s_fa_roe(B5,20211231)="0",[1]!s_fa_roe(B5,20221231)="0"),"",IFERROR(([1]!s_fa_roe(B5,20221231)+[1]!s_fa_roe(B5,20201231)+[1]!s_fa_roe(B5,20211231))/3,"")) -> 0 | P5: =IFERROR(([1]!s_stmnote_bank_65(B5,$A5,1,2,4,100000000)+[1]!s_stmnote_bank_65(B5,$A5,1,2,6,100000000))/[1]!s_stmnote_bank_1n(B5,$A5,1,100000000),"") | Q5: =IFERROR([1]!s_stmnote_bank_614(B5,$A5,1,2,100000000)/[1]!s_stmnote_bank_647(B5,$A5,1,2,100000000),"") | R5: =IFERROR(([1]!b_stm07_bs(B5,104,$A5,1,100000000)+[1]!b_stm07_bs(B5,106,$A5,1,100000000)+[1]!b_stm07_bs(B5,76,$A5,1,100000000)+[1]!b_stm07_bs(B5,108,$A5,1,100000000)+[1]!b_stm07_bs(B5,95,$A5,1,100000000))/[1]!b_stm07_bs(B5,128,$A5,1,100000000),"") | S5: =IFERROR(([1]!s_stmnote_bank_614(B5,$A5,1,2,100000000)+[1]!b_stm07_bs(B5,104,$A5,1,100000000)+[1]!b_stm07_bs(B5,106,$A5,1,100000000)+[1]!b_stm07_bs(B5,76,$A5,1,100000000)+[1]!b_stm07_bs(B5,108,$A5,1,100000000)+[1]!b_stm07_bs(B5,95,$A5,1,100000000))/[1]!b_stm07_bs(B5,128,$A5,1,100000000),"") | T5: =[1]!b_issuer_shareholder(B5,"",1) -> 0 | U5: =[1]!b_issuer_propofshareholder(B5,"",1) -> 0 | V5: =LEFT(C5,2) -> 0 | W5: =[1]!s_info_city(B5) -> 0 | X5: =IF([1]!s_stmnote_bank_17n(B5,$A5,1)="0","",[1]!s_stmnote_bank_17n(B5,$A5,1)) -> 0 | Y5: =IF([1]!s_stmnote_bank_18n(B5,$A5,1)="0","",[1]!s_stmnote_bank_18n(B5,$A5,1)) -> 0 | Z5: =IF([1]!s_stmnote_bank_58(B5,$A5,1)="0","",[1]!s_stmnote_bank_58(B5,$A5,1)) -> 0 | AA5: =IF([1]!s_stmnote_bank_60(B5,$A5,1)="0","",[1]!s_stmnote_bank_60(B5,$A5,1)) -> 0 | AB5: =[1]!s_stmnote_bank_5444(B5,$A5,1) -> 0 | AC5: =[1]!s_stmnote_bank_129n($B5,$A5,1) -> 0 | AD5: =[1]!s_stmnote_bank_30(B5,$A5,1) -> 0
A6: 2024-06-30 | B6: 091506005.IB | C6: =IF([1]!b_info_issuer(B6)="0","",IFERROR([1]!b_info_issuer(B6),"")) -> 0 | D6: =IF([1]!b_info_latestissurercreditrating(B6)="0","",IFERROR([1]!b_info_latestissurercreditrating(B6),"")) -> 0 | E6: =IFERROR(([1]!b_stm07_bs($B6,47,$A6,1,100000000))/[1]!b_stm07_bs($B6,109,$A6,1,100000000),"") | F6: =IFERROR(([1]!s_stmnote_bank_26($B6,$A6,1,100000000)-[1]!s_stmnote_bank_26($B6,#REF!,1,100000000)+#REF!)/[1]!s_stmnote_bank_1n($B6,#REF!,1,100000000),"") | G6: =IFERROR(H6+K6/100,"") | H6: =IFERROR([1]!s_stmnote_bank($B6,"34",$A6,100000000)/[1]!s_stmnote_bank_1n(B6,$A6,1,100000000),"") | I6: =[1]!b_stm07_bs(B6,74,$A6,1,100000000) -> 0 | J6: =[1]!b_stm07_bs(B6,109,$A6,1,100000000) -> 0 | K6: =[1]!s_stmnote_bank_5n(B6,$A6,1) -> 0 | L6: =[1]!s_stmnote_bank_23n(B6,$A6,1) -> 0 | M6: =[1]!s_stmnote_bank_capadequacyratio(B6,$A6,1) -> 0 | N6: =[1]!s_stmnote_bank_capadequacyratio_ct1(B6,$A6,1) -> 0 | O6: =IF(OR([1]!s_fa_roe(B6,20201231)="0",[1]!s_fa_roe(B6,20211231)="0",[1]!s_fa_roe(B6,20221231)="0"),"",IFERROR(([1]!s_fa_roe(B6,20221231)+[1]!s_fa_roe(B6,20201231)+[1]!s_fa_roe(B6,20211231))/3,"")) -> 0 | P6: =IFERROR(([1]!s_stmnote_bank_65(B6,$A6,1,2,4,100000000)+[1]!s_stmnote_bank_65(B6,$A6,1,2,6,100000000))/[1]!s_stmnote_bank_1n(B6,$A6,1,100000000),"") | Q6: =IFERROR([1]!s_stmnote_bank_614(B6,$A6,1,2,100000000)/[1]!s_stmnote_bank_647(B6,$A6,1,2,100000000),"") | R6: =IFERROR(([1]!b_stm07_bs(B6,104,$A6,1,100000000)+[1]!b_stm07_bs(B6,106,$A6,1,100000000)+[1]!b_stm07_bs(B6,76,$A6,1,100000000)+[1]!b_stm07_bs(B6,108,$A6,1,100000000)+[1]!b_stm07_bs(B6,95,$A6,1,100000000))/[1]!b_stm07_bs(B6,128,$A6,1,100000000),"") | S6: =IFERROR(([1]!s_stmnote_bank_614(B6,$A6,1,2,100000000)+[1]!b_stm07_bs(B6,104,$A6,1,100000000)+[1]!b_stm07_bs(B6,106,$A6,1,100000000)+[1]!b_stm07_bs(B6,76,$A6,1,100000000)+[1]!b_stm07_bs(B6,108,$A6,1,100000000)+[1]!b_stm07_bs(B6,95,$A6,1,100000000))/[1]!b_stm07_bs(B6,128,$A6,1,100000000),"") | T6: =[1]!b_issuer_shareholder(B6,"",1) -> 0 | U6: =[1]!b_issuer_propofshareholder(B6,"",1) -> 0 | V6: =LEFT(C6,2) -> 0 | W6: =[1]!s_info_city(B6) -> 0 | X6: =IF([1]!s_stmnote_bank_17n(B6,$A6,1)="0","",[1]!s_stmnote_bank_17n(B6,$A6,1)) -> 0 | Y6: =IF([1]!s_stmnote_bank_18n(B6,$A6,1)="0","",[1]!s_stmnote_bank_18n(B6,$A6,1)) -> 0 | Z6: =IF([1]!s_stmnote_bank_58(B6,$A6,1)="0","",[1]!s_stmnote_bank_58(B6,$A6,1)) -> 0 | AA6: =IF([1]!s_stmnote_bank_60(B6,$A6,1)="0","",[1]!s_stmnote_bank_60(B6,$A6,1)) -> 0 | AB6: =[1]!s_stmnote_bank_5444(B6,$A6,1) -> 0 | AC6: =[1]!s_stmnote_bank_129n($B6,$A6,1) -> 0 | AD6: =[1]!s_stmnote_bank_30(B6,$A6,1) -> 0
A7: 2024-06-30 | B7: 091506006.IB | C7: =IF([1]!b_info_issuer(B7)="0","",IFERROR([1]!b_info_issuer(B7),"")) -> 0 | D7: =IF([1]!b_info_latestissurercreditrating(B7)="0","",IFERROR([1]!b_info_latestissurercreditrating(B7),"")) -> 0 | E7: =IFERROR(([1]!b_stm07_bs($B7,47,$A7,1,100000000))/[1]!b_stm07_bs($B7,109,$A7,1,100000000),"") | F7: =IFERROR(([1]!s_stmnote_bank_26($B7,$A7,1,100000000)-[1]!s_stmnote_bank_26($B7,#REF!,1,100000000)+#REF!)/[1]!s_stmnote_bank_1n($B7,#REF!,1,100000000),"") | G7: =IFERROR(H7+K7/100,"") | H7: =IFERROR([1]!s_stmnote_bank($B7,"34",$A7,100000000)/[1]!s_stmnote_bank_1n(B7,$A7,1,100000000),"") | I7: =[1]!b_stm07_bs(B7,74,$A7,1,100000000) -> 0 | J7: =[1]!b_stm07_bs(B7,109,$A7,1,100000000) -> 0 | K7: =[1]!s_stmnote_bank_5n(B7,$A7,1) -> 0 | L7: =[1]!s_stmnote_bank_23n(B7,$A7,1) -> 0 | M7: =[1]!s_stmnote_bank_capadequacyratio(B7,$A7,1) -> 0 | N7: =[1]!s_stmnote_bank_capadequacyratio_ct1(B7,$A7,1) -> 0 | O7: =IF(OR([1]!s_fa_roe(B7,20201231)="0",[1]!s_fa_roe(B7,20211231)="0",[1]!s_fa_roe(B7,20221231)="0"),"",IFERROR(([1]!s_fa_roe(B7,20221231)+[1]!s_fa_roe(B7,20201231)+[1]!s_fa_roe(B7,20211231))/3,"")) -> 0 | P7: =IFERROR(([1]!s_stmnote_bank_65(B7,$A7,1,2,4,100000000)+[1]!s_stmnote_bank_65(B7,$A7,1,2,6,100000000))/[1]!s_stmnote_bank_1n(B7,$A7,1,100000000),"") | Q7: =IFERROR([1]!s_stmnote_bank_614(B7,$A7,1,2,100000000)/[1]!s_stmnote_bank_647(B7,$A7,1,2,100000000),"") | R7: =IFERROR(([1]!b_stm07_bs(B7,104,$A7,1,100000000)+[1]!b_stm07_bs(B7,106,$A7,1,100000000)+[1]!b_stm07_bs(B7,76,$A7,1,100000000)+[1]!b_stm07_bs(B7,108,$A7,1,100000000)+[1]!b_stm07_bs(B7,95,$A7,1,100000000))/[1]!b_stm07_bs(B7,128,$A7,1,100000000),"") | S7: =IFERROR(([1]!s_stmnote_bank_614(B7,$A7,1,2,100000000)+[1]!b_stm07_bs(B7,104,$A7,1,100000000)+[1]!b_stm07_bs(B7,106,$A7,1,100000000)+[1]!b_stm07_bs(B7,76,$A7,1,100000000)+[1]!b_stm07_bs(B7,108,$A7,1,100000000)+[1]!b_stm07_bs(B7,95,$A7,1,100000000))/[1]!b_stm07_bs(B7,128,$A7,1,100000000),"") | T7: =[1]!b_issuer_shareholder(B7,"",1) -> 0 | U7: =[1]!b_issuer_propofshareholder(B7,"",1) -> 0 | V7: =LEFT(C7,2) -> 0 | W7: =[1]!s_info_city(B7) -> 0 | X7: =IF([1]!s_stmnote_bank_17n(B7,$A7,1)="0","",[1]!s_stmnote_bank_17n(B7,$A7,1)) -> 0 | Y7: =IF([1]!s_stmnote_bank_18n(B7,$A7,1)="0","",[1]!s_stmnote_bank_18n(B7,$A7,1)) -> 0 | Z7: =IF([1]!s_stmnote_bank_58(B7,$A7,1)="0","",[1]!s_stmnote_bank_58(B7,$A7,1)) -> 0 | AA7: =IF([1]!s_stmnote_bank_60(B7,$A7,1)="0","",[1]!s_stmnote_bank_60(B7,$A7,1)) -> 0 | AB7: =[1]!s_stmnote_bank_5444(B7,$A7,1) -> 0 | AC7: =[1]!s_stmnote_bank_129n($B7,$A7,1) -> 0 | AD7: =[1]!s_stmnote_bank_30(B7,$A7,1) -> 0
A8: 2024-06-30 | B8: 091506007.IB | C8: =IF([1]!b_info_issuer(B8)="0","",IFERROR([1]!b_info_issuer(B8),"")) -> 0 | D8: =IF([1]!b_info_latestissurercreditrating(B8)="0","",IFERROR([1]!b_info_latestissurercreditrating(B8),"")) -> 0 | E8: =IFERROR(([1]!b_stm07_bs($B8,47,$A8,1,100000000))/[1]!b_stm07_bs($B8,109,$A8,1,100000000),"") | F8: =IFERROR(([1]!s_stmnote_bank_26($B8,$A8,1,100000000)-[1]!s_stmnote_bank_26($B8,#REF!,1,100000000)+#REF!)/[1]!s_stmnote_bank_1n($B8,#REF!,1,100000000),"") | G8: =IFERROR(H8+K8/100,"") | H8: =IFERROR([1]!s_stmnote_bank($B8,"34",$A8,100000000)/[1]!s_stmnote_bank_1n(B8,$A8,1,100000000),"") | I8: =[1]!b_stm07_bs(B8,74,$A8,1,100000000) -> 0 | J8: =[1]!b_stm07_bs(B8,109,$A8,1,100000000) -> 0 | K8: =[1]!s_stmnote_bank_5n(B8,$A8,1) -> 0 | L8: =[1]!s_stmnote_bank_23n(B8,$A8,1) -> 0 | M8: =[1]!s_stmnote_bank_capadequacyratio(B8,$A8,1) -> 0 | N8: =[1]!s_stmnote_bank_capadequacyratio_ct1(B8,$A8,1) -> 0 | O8: =IF(OR([1]!s_fa_roe(B8,20201231)="0",[1]!s_fa_roe(B8,20211231)="0",[1]!s_fa_roe(B8,20221231)="0"),"",IFERROR(([1]!s_fa_roe(B8,20221231)+[1]!s_fa_roe(B8,20201231)+[1]!s_fa_roe(B8,20211231))/3,"")) -> 0 | P8: =IFERROR(([1]!s_stmnote_bank_65(B8,$A8,1,2,4,100000000)+[1]!s_stmnote_bank_65(B8,$A8,1,2,6,100000000))/[1]!s_stmnote_bank_1n(B8,$A8,1,100000000),"") | Q8: =IFERROR([1]!s_stmnote_bank_614(B8,$A8,1,2,100000000)/[1]!s_stmnote_bank_647(B8,$A8,1,2,100000000),"") | R8: =IFERROR(([1]!b_stm07_bs(B8,104,$A8,1,100000000)+[1]!b_stm07_bs(B8,106,$A8,1,100000000)+[1]!b_stm07_bs(B8,76,$A8,1,100000000)+[1]!b_stm07_bs(B8,108,$A8,1,100000000)+[1]!b_stm07_bs(B8,95,$A8,1,100000000))/[1]!b_stm07_bs(B8,128,$A8,1,100000000),"") | S8: =IFERROR(([1]!s_stmnote_bank_614(B8,$A8,1,2,100000000)+[1]!b_stm07_bs(B8,104,$A8,1,100000000)+[1]!b_stm07_bs(B8,106,$A8,1,100000000)+[1]!b_stm07_bs(B8,76,$A8,1,100000000)+[1]!b_stm07_bs(B8,108,$A8,1,100000000)+[1]!b_stm07_bs(B8,95,$A8,1,100000000))/[1]!b_stm07_bs(B8,128,$A8,1,100000000),"") | T8: =[1]!b_issuer_shareholder(B8,"",1) -> 0 | U8: =[1]!b_issuer_propofshareholder(B8,"",1) -> 0 | V8: =LEFT(C8,2) -> 0 | W8: =[1]!s_info_city(B8) -> 0 | X8: =IF([1]!s_stmnote_bank_17n(B8,$A8,1)="0","",[1]!s_stmnote_bank_17n(B8,$A8,1)) -> 0 | Y8: =IF([1]!s_stmnote_bank_18n(B8,$A8,1)="0","",[1]!s_stmnote_bank_18n(B8,$A8,1)) -> 0 | Z8: =IF([1]!s_stmnote_bank_58(B8,$A8,1)="0","",[1]!s_stmnote_bank_58(B8,$A8,1)) -> 0 | AA8: =IF([1]!s_stmnote_bank_60(B8,$A8,1)="0","",[1]!s_stmnote_bank_60(B8,$A8,1)) -> 0 | AB8: =[1]!s_stmnote_bank_5444(B8,$A8,1) -> 0 | AC8: =[1]!s_stmnote_bank_129n($B8,$A8,1) -> 0 | AD8: =[1]!s_stmnote_bank_30(B8,$A8,1) -> 0
A9: 2024-06-30 | B9: 091506008.IB | C9: =IF([1]!b_info_issuer(B9)="0","",IFERROR([1]!b_info_issuer(B9),"")) -> 0 | D9: =IF([1]!b_info_latestissurercreditrating(B9)="0","",IFERROR([1]!b_info_latestissurercreditrating(B9),"")) -> 0 | E9: =IFERROR(([1]!b_stm07_bs($B9,47,$A9,1,100000000))/[1]!b_stm07_bs($B9,109,$A9,1,100000000),"") | F9: =IFERROR(([1]!s_stmnote_bank_26($B9,$A9,1,100000000)-[1]!s_stmnote_bank_26($B9,#REF!,1,100000000)+#REF!)/[1]!s_stmnote_bank_1n($B9,#REF!,1,100000000),"") | G9: =IFERROR(H9+K9/100,"") | H9: =IFERROR([1]!s_stmnote_bank($B9,"34",$A9,100000000)/[1]!s_stmnote_bank_1n(B9,$A9,1,100000000),"") | I9: =[1]!b_stm07_bs(B9,74,$A9,1,100000000) -> 0 | J9: =[1]!b_stm07_bs(B9,109,$A9,1,100000000) -> 0 | K9: =[1]!s_stmnote_bank_5n(B9,$A9,1) -> 0 | L9: =[1]!s_stmnote_bank_23n(B9,$A9,1) -> 0 | M9: =[1]!s_stmnote_bank_capadequacyratio(B9,$A9,1) -> 0 | N9: =[1]!s_stmnote_bank_capadequacyratio_ct1(B9,$A9,1) -> 0 | O9: =IF(OR([1]!s_fa_roe(B9,20201231)="0",[1]!s_fa_roe(B9,20211231)="0",[1]!s_fa_roe(B9,20221231)="0"),"",IFERROR(([1]!s_fa_roe(B9,20221231)+[1]!s_fa_roe(B9,20201231)+[1]!s_fa_roe(B9,20211231))/3,"")) -> 0 | P9: =IFERROR(([1]!s_stmnote_bank_65(B9,$A9,1,2,4,100000000)+[1]!s_stmnote_bank_65(B9,$A9,1,2,6,100000000))/[1]!s_stmnote_bank_1n(B9,$A9,1,100000000),"") | Q9: =IFERROR([1]!s_stmnote_bank_614(B9,$A9,1,2,100000000)/[1]!s_stmnote_bank_647(B9,$A9,1,2,100000000),"") | R9: =IFERROR(([1]!b_stm07_bs(B9,104,$A9,1,100000000)+[1]!b_stm07_bs(B9,106,$A9,1,100000000)+[1]!b_stm07_bs(B9,76,$A9,1,100000000)+[1]!b_stm07_bs(B9,108,$A9,1,100000000)+[1]!b_stm07_bs(B9,95,$A9,1,100000000))/[1]!b_stm07_bs(B9,128,$A9,1,100000000),"") | S9: =IFERROR(([1]!s_stmnote_bank_614(B9,$A9,1,2,100000000)+[1]!b_stm07_bs(B9,104,$A9,1,100000000)+[1]!b_stm07_bs(B9,106,$A9,1,100000000)+[1]!b_stm07_bs(B9,76,$A9,1,100000000)+[1]!b_stm07_bs(B9,108,$A9,1,100000000)+[1]!b_stm07_bs(B9,95,$A9,1,100000000))/[1]!b_stm07_bs(B9,128,$A9,1,100000000),"") | T9: =[1]!b_issuer_shareholder(B9,"",1) -> 0 | U9: =[1]!b_issuer_propofshareholder(B9,"",1) -> 0 | V9: =LEFT(C9,2) -> 0 | W9: =[1]!s_info_city(B9) -> 0 | X9: =IF([1]!s_stmnote_bank_17n(B9,$A9,1)="0","",[1]!s_stmnote_bank_17n(B9,$A9,1)) -> 0 | Y9: =IF([1]!s_stmnote_bank_18n(B9,$A9,1)="0","",[1]!s_stmnote_bank_18n(B9,$A9,1)) -> 0 | Z9: =IF([1]!s_stmnote_bank_58(B9,$A9,1)="0","",[1]!s_stmnote_bank_58(B9,$A9,1)) -> 0 | AA9: =IF([1]!s_stmnote_bank_60(B9,$A9,1)="0","",[1]!s_stmnote_bank_60(B9,$A9,1)) -> 0 | AB9: =[1]!s_stmnote_bank_5444(B9,$A9,1) -> 0 | AC9: =[1]!s_stmnote_bank_129n($B9,$A9,1) -> 0 | AD9: =[1]!s_stmnote_bank_30(B9,$A9,1) -> 0
A10: 2024-06-30 | B10: 091506009.IB | C10: =IF([1]!b_info_issuer(B10)="0","",IFERROR([1]!b_info_issuer(B10),"")) -> 0 | D10: =IF([1]!b_info_latestissurercreditrating(B10)="0","",IFERROR([1]!b_info_latestissurercreditrating(B10),"")) -> 0 | E10: =IFERROR(([1]!b_stm07_bs($B10,47,$A10,1,100000000))/[1]!b_stm07_bs($B10,109,$A10,1,100000000),"") | F10: =IFERROR(([1]!s_stmnote_bank_26($B10,$A10,1,100000000)-[1]!s_stmnote_bank_26($B10,#REF!,1,100000000)+#REF!)/[1]!s_stmnote_bank_1n($B10,#REF!,1,100000000),"") | G10: =IFERROR(H10+K10/100,"") | H10: =IFERROR([1]!s_stmnote_bank($B10,"34",$A10,100000000)/[1]!s_stmnote_bank_1n(B10,$A10,1,100000000),"") | I10: =[1]!b_stm07_bs(B10,74,$A10,1,100000000) -> 0 | J10: =[1]!b_stm07_bs(B10,109,$A10,1,100000000) -> 0 | K10: =[1]!s_stmnote_bank_5n(B10,$A10,1) -> 0 | L10: =[1]!s_stmnote_bank_23n(B10,$A10,1) -> 0 | M10: =[1]!s_stmnote_bank_capadequacyratio(B10,$A10,1) -> 0 | N10: =[1]!s_stmnote_bank_capadequacyratio_ct1(B10,$A10,1) -> 0 | O10: =IF(OR([1]!s_fa_roe(B10,20201231)="0",[1]!s_fa_roe(B10,20211231)="0",[1]!s_fa_roe(B10,20221231)="0"),"",IFERROR(([1]!s_fa_roe(B10,20221231)+[1]!s_fa_roe(B10,20201231)+[1]!s_fa_roe(B10,20211231))/3,"")) -> 0 | P10: =IFERROR(([1]!s_stmnote_bank_65(B10,$A10,1,2,4,100000000)+[1]!s_stmnote_bank_65(B10,$A10,1,2,6,100000000))/[1]!s_stmnote_bank_1n(B10,$A10,1,100000000),"") | Q10: =IFERROR([1]!s_stmnote_bank_614(B10,$A10,1,2,100000000)/[1]!s_stmnote_bank_647(B10,$A10,1,2,100000000),"") | R10: =IFERROR(([1]!b_stm07_bs(B10,104,$A10,1,100000000)+[1]!b_stm07_bs(B10,106,$A10,1,100000000)+[1]!b_stm07_bs(B10,76,$A10,1,100000000)+[1]!b_stm07_bs(B10,108,$A10,1,100000000)+[1]!b_stm07_bs(B10,95,$A10,1,100000000))/[1]!b_stm07_bs(B10,128,$A10,1,100000000),"") | S10: =IFERROR(([1]!s_stmnote_bank_614(B10,$A10,1,2,100000000)+[1]!b_stm07_bs(B10,104,$A10,1,100000000)+[1]!b_stm07_bs(B10,106,$A10,1,100000000)+[1]!b_stm07_bs(B10,76,$A10,1,100000000)+[1]!b_stm07_bs(B10,108,$A10,1,100000000)+[1]!b_stm07_bs(B10,95,$A10,1,100000000))/[1]!b_stm07_bs(B10,128,$A10,1,100000000),"") | T10: =[1]!b_issuer_shareholder(B10,"",1) -> 0 | U10: =[1]!b_issuer_propofshareholder(B10,"",1) -> 0 | V10: =LEFT(C10,2) -> 0 | W10: =[1]!s_info_city(B10) -> 0 | X10: =IF([1]!s_stmnote_bank_17n(B10,$A10,1)="0","",[1]!s_stmnote_bank_17n(B10,$A10,1)) -> 0 | Y10: =IF([1]!s_stmnote_bank_18n(B10,$A10,1)="0","",[1]!s_stmnote_bank_18n(B10,$A10,1)) -> 0 | Z10: =IF([1]!s_stmnote_bank_58(B10,$A10,1)="0","",[1]!s_stmnote_bank_58(B10,$A10,1)) -> 0 | AA10: =IF([1]!s_stmnote_bank_60(B10,$A10,1)="0","",[1]!s_stmnote_bank_60(B10,$A10,1)) -> 0 | AB10: =[1]!s_stmnote_bank_5444(B10,$A10,1) -> 0 | AC10: =[1]!s_stmnote_bank_129n($B10,$A10,1) -> 0 | AD10: =[1]!s_stmnote_bank_30(B10,$A10,1) -> 0
A11: 2024-06-30 | B11: 091506010.IB | C11: =IF([1]!b_info_issuer(B11)="0","",IFERROR([1]!b_info_issuer(B11),"")) -> 0 | D11: =IF([1]!b_info_latestissurercreditrating(B11)="0","",IFERROR([1]!b_info_latestissurercreditrating(B11),"")) -> 0 | E11: =IFERROR(([1]!b_stm07_bs($B11,47,$A11,1,100000000))/[1]!b_stm07_bs($B11,109,$A11,1,100000000),"") | F11: =IFERROR(([1]!s_stmnote_bank_26($B11,$A11,1,100000000)-[1]!s_stmnote_bank_26($B11,#REF!,1,100000000)+#REF!)/[1]!s_stmnote_bank_1n($B11,#REF!,1,100000000),"") | G11: =IFERROR(H11+K11/100,"") | H11: =IFERROR([1]!s_stmnote_bank($B11,"34",$A11,100000000)/[1]!s_stmnote_bank_1n(B11,$A11,1,100000000),"") | I11: =[1]!b_stm07_bs(B11,74,$A11,1,100000000) -> 0 | J11: =[1]!b_stm07_bs(B11,109,$A11,1,100000000) -> 0 | K11: =[1]!s_stmnote_bank_5n(B11,$A11,1) -> 0 | L11: =[1]!s_stmnote_bank_23n(B11,$A11,1) -> 0 | M11: =[1]!s_stmnote_bank_capadequacyratio(B11,$A11,1) -> 0 | N11: =[1]!s_stmnote_bank_capadequacyratio_ct1(B11,$A11,1) -> 0 | O11: =IF(OR([1]!s_fa_roe(B11,20201231)="0",[1]!s_fa_roe(B11,20211231)="0",[1]!s_fa_roe(B11,20221231)="0"),"",IFERROR(([1]!s_fa_roe(B11,20221231)+[1]!s_fa_roe(B11,20201231)+[1]!s_fa_roe(B11,20211231))/3,"")) -> 0 | P11: =IFERROR(([1]!s_stmnote_bank_65(B11,$A11,1,2,4,100000000)+[1]!s_stmnote_bank_65(B11,$A11,1,2,6,100000000))/[1]!s_stmnote_bank_1n(B11,$A11,1,100000000),"") | Q11: =IFERROR([1]!s_stmnote_bank_614(B11,$A11,1,2,100000000)/[1]!s_stmnote_bank_647(B11,$A11,1,2,100000000),"") | R11: =IFERROR(([1]!b_stm07_bs(B11,104,$A11,1,100000000)+[1]!b_stm07_bs(B11,106,$A11,1,100000000)+[1]!b_stm07_bs(B11,76,$A11,1,100000000)+[1]!b_stm07_bs(B11,108,$A11,1,100000000)+[1]!b_stm07_bs(B11,95,$A11,1,100000000))/[1]!b_stm07_bs(B11,128,$A11,1,100000000),"") | S11: =IFERROR(([1]!s_stmnote_bank_614(B11,$A11,1,2,100000000)+[1]!b_stm07_bs(B11,104,$A11,1,100000000)+[1]!b_stm07_bs(B11,106,$A11,1,100000000)+[1]!b_stm07_bs(B11,76,$A11,1,100000000)+[1]!b_stm07_bs(B11,108,$A11,1,100000000)+[1]!b_stm07_bs(B11,95,$A11,1,100000000))/[1]!b_stm07_bs(B11,128,$A11,1,100000000),"") | T11: =[1]!b_issuer_shareholder(B11,"",1) -> 0 | U11: =[1]!b_issuer_propofshareholder(B11,"",1) -> 0 | V11: =LEFT(C11,2) -> 0 | W11: =[1]!s_info_city(B11) -> 0 | X11: =IF([1]!s_stmnote_bank_17n(B11,$A11,1)="0","",[1]!s_stmnote_bank_17n(B11,$A11,1)) -> 0 | Y11: =IF([1]!s_stmnote_bank_18n(B11,$A11,1)="0","",[1]!s_stmnote_bank_18n(B11,$A11,1)) -> 0 | Z11: =IF([1]!s_stmnote_bank_58(B11,$A11,1)="0","",[1]!s_stmnote_bank_58(B11,$A11,1)) -> 0 | AA11: =IF([1]!s_stmnote_bank_60(B11,$A11,1)="0","",[1]!s_stmnote_bank_60(B11,$A11,1)) -> 0 | AB11: =[1]!s_stmnote_bank_5444(B11,$A11,1) -> 0 | AC11: =[1]!s_stmnote_bank_129n($B11,$A11,1) -> 0 | AD11: =[1]!s_stmnote_bank_30(B11,$A11,1) -> 0
A12: 2024-06-30 | B12: 091506011.IB | C12: =IF([1]!b_info_issuer(B12)="0","",IFERROR([1]!b_info_issuer(B12),"")) -> 0 | D12: =IF([1]!b_info_latestissurercreditrating(B12)="0","",IFERROR([1]!b_info_latestissurercreditrating(B12),"")) -> 0 | E12: =IFERROR(([1]!b_stm07_bs($B12,47,$A12,1,100000000))/[1]!b_stm07_bs($B12,109,$A12,1,100000000),"") | F12: =IFERROR(([1]!s_stmnote_bank_26($B12,$A12,1,100000000)-[1]!s_stmnote_bank_26($B12,#REF!,1,100000000)+#REF!)/[1]!s_stmnote_bank_1n($B12,#REF!,1,100000000),"") | G12: =IFERROR(H12+K12/100,"") | H12: =IFERROR([1]!s_stmnote_bank($B12,"34",$A12,100000000)/[1]!s_stmnote_bank_1n(B12,$A12,1,100000000),"") | I12: =[1]!b_stm07_bs(B12,74,$A12,1,100000000) -> 0 | J12: =[1]!b_stm07_bs(B12,109,$A12,1,100000000) -> 0 | K12: =[1]!s_stmnote_bank_5n(B12,$A12,1) -> 0 | L12: =[1]!s_stmnote_bank_23n(B12,$A12,1) -> 0 | M12: =[1]!s_stmnote_bank_capadequacyratio(B12,$A12,1) -> 0 | N12: =[1]!s_stmnote_bank_capadequacyratio_ct1(B12,$A12,1) -> 0 | O12: =IF(OR([1]!s_fa_roe(B12,20201231)="0",[1]!s_fa_roe(B12,20211231)="0",[1]!s_fa_roe(B12,20221231)="0"),"",IFERROR(([1]!s_fa_roe(B12,20221231)+[1]!s_fa_roe(B12,20201231)+[1]!s_fa_roe(B12,20211231))/3,"")) -> 0 | P12: =IFERROR(([1]!s_stmnote_bank_65(B12,$A12,1,2,4,100000000)+[1]!s_stmnote_bank_65(B12,$A12,1,2,6,100000000))/[1]!s_stmnote_bank_1n(B12,$A12,1,100000000),"") | Q12: =IFERROR([1]!s_stmnote_bank_614(B12,$A12,1,2,100000000)/[1]!s_stmnote_bank_647(B12,$A12,1,2,100000000),"") | R12: =IFERROR(([1]!b_stm07_bs(B12,104,$A12,1,100000000)+[1]!b_stm07_bs(B12,106,$A12,1,100000000)+[1]!b_stm07_bs(B12,76,$A12,1,100000000)+[1]!b_stm07_bs(B12,108,$A12,1,100000000)+[1]!b_stm07_bs(B12,95,$A12,1,100000000))/[1]!b_stm07_bs(B12,128,$A12,1,100000000),"") | S12: =IFERROR(([1]!s_stmnote_bank_614(B12,$A12,1,2,100000000)+[1]!b_stm07_bs(B12,104,$A12,1,100000000)+[1]!b_stm07_bs(B12,106,$A12,1,100000000)+[1]!b_stm07_bs(B12,76,$A12,1,100000000)+[1]!b_stm07_bs(B12,108,$A12,1,100000000)+[1]!b_stm07_bs(B12,95,$A12,1,100000000))/[1]!b_stm07_bs(B12,128,$A12,1,100000000),"") | T12: =[1]!b_issuer_shareholder(B12,"",1) -> 0 | U12: =[1]!b_issuer_propofshareholder(B12,"",1) -> 0 | V12: =LEFT(C12,2) -> 0 | W12: =[1]!s_info_city(B12) -> 0 | X12: =IF([1]!s_stmnote_bank_17n(B12,$A12,1)="0","",[1]!s_stmnote_bank_17n(B12,$A12,1)) -> 0 | Y12: =IF([1]!s_stmnote_bank_18n(B12,$A12,1)="0","",[1]!s_stmnote_bank_18n(B12,$A12,1)) -> 0 | Z12: =IF([1]!s_stmnote_bank_58(B12,$A12,1)="0","",[1]!s_stmnote_bank_58(B12,$A12,1)) -> 0 | AA12: =IF([1]!s_stmnote_bank_60(B12,$A12,1)="0","",[1]!s_stmnote_bank_60(B12,$A12,1)) -> 0 | AB12: =[1]!s_stmnote_bank_5444(B12,$A12,1) -> 0 | AC12: =[1]!s_stmnote_bank_129n($B12,$A12,1) -> 0 | AD12: =[1]!s_stmnote_bank_30(B12,$A12,1) -> 0
A13: 2024-06-30 | B13: 091506012.IB | C13: =IF([1]!b_info_issuer(B13)="0","",IFERROR([1]!b_info_issuer(B13),"")) -> 0 | D13: =IF([1]!b_info_latestissurercreditrating(B13)="0","",IFERROR([1]!b_info_latestissurercreditrating(B13),"")) -> 0 | E13: =IFERROR(([1]!b_stm07_bs($B13,47,$A13,1,100000000))/[1]!b_stm07_bs($B13,109,$A13,1,100000000),"") | F13: =IFERROR(([1]!s_stmnote_bank_26($B13,$A13,1,100000000)-[1]!s_stmnote_bank_26($B13,#REF!,1,100000000)+#REF!)/[1]!s_stmnote_bank_1n($B13,#REF!,1,100000000),"") | G13: =IFERROR(H13+K13/100,"") | H13: =IFERROR([1]!s_stmnote_bank($B13,"34",$A13,100000000)/[1]!s_stmnote_bank_1n(B13,$A13,1,100000000),"") | I13: =[1]!b_stm07_bs(B13,74,$A13,1,100000000) -> 0 | J13: =[1]!b_stm07_bs(B13,109,$A13,1,100000000) -> 0 | K13: =[1]!s_stmnote_bank_5n(B13,$A13,1) -> 0 | L13: =[1]!s_stmnote_bank_23n(B13,$A13,1) -> 0 | M13: =[1]!s_stmnote_bank_capadequacyratio(B13,$A13,1) -> 0 | N13: =[1]!s_stmnote_bank_capadequacyratio_ct1(B13,$A13,1) -> 0 | O13: =IF(OR([1]!s_fa_roe(B13,20201231)="0",[1]!s_fa_roe(B13,20211231)="0",[1]!s_fa_roe(B13,20221231)="0"),"",IFERROR(([1]!s_fa_roe(B13,20221231)+[1]!s_fa_roe(B13,20201231)+[1]!s_fa_roe(B13,20211231))/3,"")) -> 0 | P13: =IFERROR(([1]!s_stmnote_bank_65(B13,$A13,1,2,4,100000000)+[1]!s_stmnote_bank_65(B13,$A13,1,2,6,100000000))/[1]!s_stmnote_bank_1n(B13,$A13,1,100000000),"") | Q13: =IFERROR([1]!s_stmnote_bank_614(B13,$A13,1,2,100000000)/[1]!s_stmnote_bank_647(B13,$A13,1,2,100000000),"") | R13: =IFERROR(([1]!b_stm07_bs(B13,104,$A13,1,100000000)+[1]!b_stm07_bs(B13,106,$A13,1,100000000)+[1]!b_stm07_bs(B13,76,$A13,1,100000000)+[1]!b_stm07_bs(B13,108,$A13,1,100000000)+[1]!b_stm07_bs(B13,95,$A13,1,100000000))/[1]!b_stm07_bs(B13,128,$A13,1,100000000),"") | S13: =IFERROR(([1]!s_stmnote_bank_614(B13,$A13,1,2,100000000)+[1]!b_stm07_bs(B13,104,$A13,1,100000000)+[1]!b_stm07_bs(B13,106,$A13,1,100000000)+[1]!b_stm07_bs(B13,76,$A13,1,100000000)+[1]!b_stm07_bs(B13,108,$A13,1,100000000)+[1]!b_stm07_bs(B13,95,$A13,1,100000000))/[1]!b_stm07_bs(B13,128,$A13,1,100000000),"") | T13: =[1]!b_issuer_shareholder(B13,"",1) -> 0 | U13: =[1]!b_issuer_propofshareholder(B13,"",1) -> 0 | V13: =LEFT(C13,2) -> 0 | W13: =[1]!s_info_city(B13) -> 0 | X13: =IF([1]!s_stmnote_bank_17n(B13,$A13,1)="0","",[1]!s_stmnote_bank_17n(B13,$A13,1)) -> 0 | Y13: =IF([1]!s_stmnote_bank_18n(B13,$A13,1)="0","",[1]!s_stmnote_bank_18n(B13,$A13,1)) -> 0 | Z13: =IF([1]!s_stmnote_bank_58(B13,$A13,1)="0","",[1]!s_stmnote_bank_58(B13,$A13,1)) -> 0 | AA13: =IF([1]!s_stmnote_bank_60(B13,$A13,1)="0","",[1]!s_stmnote_bank_60(B13,$A13,1)) -> 0 | AB13: =[1]!s_stmnote_bank_5444(B13,$A13,1) -> 0 | AC13: =[1]!s_stmnote_bank_129n($B13,$A13,1) -> 0 | AD13: =[1]!s_stmnote_bank_30(B13,$A13,1) -> 0
... A568: 2024-06-30 | B568: 091506567.IB | C568: =IF([1]!b_info_issuer(B568)="0","",IFERROR([1]!b_info_issuer(B568),"")) -> 0 | D568: =IF([1]!b_info_latestissurercreditrating(B568)="0","",IFERROR([1]!b_info_latestissurercreditrating(B568),"")) -> 0 | E568: =IFERROR(([1]!b_stm07_bs($B568,47,$A568,1,100000000))/[1]!b_stm07_bs($B568,109,$A568,1,100000000),"") | F568: =IFERROR(([1]!s_stmnote_bank_26($B568,$A568,1,100000000)-[1]!s_stmnote_bank_26($B568,#REF!,1,100000000)+#REF!)/[1]!s_stmnote_bank_1n($B568,#REF!,1,100000000),"") | G568: =IFERROR(H568+K568/100,"") | H568: =IFERROR([1]!s_stmnote_bank($B568,"34",$A568,100000000)/[1]!s_stmnote_bank_1n(B568,$A568,1,100000000),"") | I568: =[1]!b_stm07_bs(B568,74,$A568,1,100000000) -> 0 | J568: =[1]!b_stm07_bs(B568,109,$A568,1,100000000) -> 0 | K568: =[1]!s_stmnote_bank_5n(B568,$A568,1) -> 0 | L568: =[1]!s_stmnote_bank_23n(B568,$A568,1) -> 0 | M568: =[1]!s_stmnote_bank_capadequacyratio(B568,$A568,1) -> 0 | N568: =[1]!s_stmnote_bank_capadequacyratio_ct1(B568,$A568,1) -> 0 | O568: =IF(OR([1]!s_fa_roe(B568,20201231)="0",[1]!s_fa_roe(B568,20211231)="0",[1]!s_fa_roe(B568,20221231)="0"),"",IFERROR(([1]!s_fa_roe(B568,20221231)+[1]!s_fa_roe(B568,20201231)+[1]!s_fa_roe(B568,20211231))/3,"")) -> 0 | P568: =IFERROR(([1]!s_stmnote_bank_65(B568,$A568,1,2,4,100000000)+[1]!s_stmnote_bank_65(B568,$A568,1,2,6,100000000))/[1]!s_stmnote_bank_1n(B568,$A568,1,100000000),"") | Q568: =IFERROR([1]!s_stmnote_bank_614(B568,$A568,1,2,100000000)/[1]!s_stmnote_bank_647(B568,$A568,1,2,100000000),"") | R568: =IFERROR(([1]!b_stm07_bs(B568,104,$A568,1,100000000)+[1]!b_stm07_bs(B568,106,$A568,1,100000000)+[1]!b_stm07_bs(B568,76,$A568,1,100000000)+[1]!b_stm07_bs(B568,108,$A568,1,100000000)+[1]!b_stm07_bs(B568,95,$A568,1,100000000))/[1]!b_stm07_bs(B568,128,$A568,1,100000000),"") | S568: =IFERROR(([1]!s_stmnote_bank_614(B568,$A568,1,2,100000000)+[1]!b_stm07_bs(B568,104,$A568,1,100000000)+[1]!b_stm07_bs(B568,106,$A568,1,100000000)+[1]!b_stm07_bs(B568,76,$A568,1,100000000)+[1]!b_stm07_bs(B568,108,$A568,1,100000000)+[1]!b_stm07_bs(B568,95,$A568,1,100000000))/[1]!b_stm07_bs(B568,128,$A568,1,100000000),"") | T568: =[1]!b_issuer_shareholder(B568,"",1) -> 0 | U568: =[1]!b_issuer_propofshareholder(B568,"",1) -> 0 | V568: =LEFT(C568,2) -> 0 | W568: =[1]!s_info_city(B568) -> 0 | X568: =IF([1]!s_stmnote_bank_17n(B568,$A568,1)="0","",[1]!s_stmnote_bank_17n(B568,$A568,1)) -> 0 | Y568: =IF([1]!s_stmnote_bank_18n(B568,$A568,1)="0","",[1]!s_stmnote_bank_18n(B568,$A568,1)) -> 0 | Z568: =IF([1]!s_stmnote_bank_58(B568,$A568,1)="0","",[1]!s_stmnote_bank_58(B568,$A568,1)) -> 0 | AA568: =IF([1]!s_stmnote_bank_60(B568,$A568,1)="0","",[1]!s_stmnote_bank_60(B568,$A568,1)) -> 0 | AB568: =[1]!s_stmnote_bank_5444(B568,$A568,1) -> 0 | AC568: =[1]!s_stmnote_bank_129n($B568,$A568,1) -> 0 | AD568: =[1]!s_stmnote_bank_30(B568,$A568,1) -> 0

Sheet 22年 (2)
A1: 20211231 | B1: 20201231 | C1: 20191231 | D1: 20220630 | E1: 20210930 | F1: 20210630 | G1: 20210331 | H1: 金融债或存单市场表现对应内评(优先金融债，无存续金融债则取存单表现） | I1: 新内评 | J1: 持仓(截至2023811） | K1: 简评 | L1: 现金/存款 | M1: 贷款资产质量 | U1: 非信贷资产质量 | Z1: 定量指标 | AJ1: 地产+建筑贷款/总贷款 | AK1: 对公活期存款/总存款 | AL1: 同业资金/总负债 | AM1: 对公活期存款+同业资金/总负债 | AN1: 定量打分 | AV1: 定性指标 | AY1: 定性打分 | BC1: 总计分 | BD1: 模型评级 | BE1: 外部支持 | BF1: 其他调整 | BG1: 备注 | BH1: 外部支持 | BJ1: 业务运营 | BL1: 集中度 | BN1: 盈利拆分（公布口径） | BQ1: 成本收入比 | BR1: 盈利拆分（计算口径） | CJ1: 非息收入占比 | CK1: 贷款利息收入 | CL1: 投资类收入 | CM1: 平均贷款收益率 | CN1: 存款利息支出 | CO1: 平均存款收益率 | CR1: 22年末ROE | CT1: 23年中ROE | CU1: 23年中ROE排位 | CV1: 22年贷款规模 | CW1: 个人贷款规模 | CX1: 个人贷款占比
A2: 证券代码 | B2: 发行人中文名称 | C2: 简称 | D2: 分类 | E2: 是否有额度 | F2: 最新外评 | G2: 原内评 | M2: 不良资产处置（核销+转让+现金清收+证券化+抵债等方式） | N2: 不良生成率 | O2: 不良生成率排序 | P2: 不良+关注 | Q2: 不良+关注行业排序 | R2: 关注类占比 | S2: 二阶段占比 | T2: 三阶段占比 | U2: 非标/总资产 | V2: 非标逾期占比 | W2: 二阶段/(金融投资+特殊报表科目） | X2: 三阶段/(金融投资+特殊报表科目） | Y2: 三阶段减值准备/三阶段 | Z2: 资产规模 | AA2: 吸收存款 | AB2: 不良贷款率 | AC2: 拨备覆盖率 | AD2: 拨备排位 | AE2: 资本充足率 | AF2: 核心一级资本充足率 | AG2: 核心资本排位 | AH2: ROE(3年移动平均） | AI2: ROE(3年移动平均）排位 | AN2: 资产规模 | AO2: 吸收存款 | AP2: 不良率 | AQ2: 拨备覆盖率 | AR2: 资本充足率 | AS2: 核心一级资本充足率 | AT2: ROE(3年移动平均） | AU2: 定量打分 | AV2: =#REF! -> #REF! | AW2: =#REF! -> #REF! | AX2: =#REF! -> #REF! | AY2: 区域环境及增长潜力 | AZ2: 信贷资产五级分类偏离度 | BA2: 非信贷资产质量 | BB2: 定性总分 | BH2: 第一大股东 | BI2: 第一大股东持股比例 | BJ2: 所在省 | BK2: 所在地 | BL2: 单一最大贷客户款占资本净额比例 | BM2: 最大十家客户贷款占资本净额比例 | BN2: 生息资产收益率 | BO2: 计息负债平均成本 | BP2: 净息差 | BR2: 生息资产收益率 | BY2: 计息负债平均成本 | CF2: 净息差 | CG2: 净息差排序 | CH2: 净息差/（不良+关注） | CI2: 净息差/（不良+关注）排序 | CP2: 22年末净资产 | CQ2: 22年中净资产 | CR2: 22年末ROE | CS2: 22年末ROE排位 | CT2: 23年中ROE | CU2: 23年中ROE
A3: 参数行，勿删 | AN3: 0.2 | AO3: 0.2 | AP3: 0.18 | AQ3: 0.12 | AR3: 0.09 | AS3: 0.12 | AT3: 0.09
A4: 公式行，勿删 | B4: =IF([1]!b_info_issuer(A4)="0","",IFERROR([1]!b_info_issuer(A4),"")) -> 0 | C4: =IF([1]!b_issuer_issuershortened(A4)="0","",IFERROR([1]!b_issuer_issuershortened(A4),"")) -> 0 | F4: =IF([1]!b_info_latestissurercreditrating(A4)="0","",IFERROR([1]!b_info_latestissurercreditrating(A4),"")) -> 0 | G4: =_xlfn.IFNA(VLOOKUP(B4,'[2]主表-22'!$C:$H,5,0),"") | L4: =IFERROR(([1]!b_stm07_bs($A4,47,$A$1,1,100000000))/[1]!b_stm07_bs($A4,109,$A$1,1,100000000),"") | N4: =IFERROR(([1]!s_stmnote_bank_26($A4,$A$1,1,100000000)-[1]!s_stmnote_bank_26($A4,$B$1,1,100000000)+M4)/[1]!s_stmnote_bank_1n($A4,$B$1,1,100000000),"") | O4: =RANK(N4,N$5:N$192,1)&" "&COUNTIF(N$5:N$192,">0") -> #VALUE! | P4: =IF(IFERROR(R4+AB4/100,"")=0,"",IFERROR(R4+AB4/100,"")) | Q4: =RANK(P4,P$5:P$192,1)&" "&COUNTIF(P$5:P$192,">0") -> #VALUE! | R4: =IFERROR([1]!s_stmnote_bank($A4,"34",$A$1,100000000)/[1]!s_stmnote_bank_1n(A4,$A$1,1,100000000),"") | S4: =IFERROR((1113.54+22.69)/[1]!s_stmnote_bank_1n(A4,$A$1,1,100000000),"") | T4: =IFERROR((508.62)/[1]!s_stmnote_bank_1n(A4,$A$1,1,100000000),"") | U4: =IFERROR((1298.51)/[1]!b_stm07_bs($A4,74,$A$1,1,100000000),"") | W4: =IFERROR((22.36)/([1]!s_stm07_bs_fininv($A4,$A$1,1,100000000)+[1]!s_stm07_bs_71($A4,$A$1,1,100000000)),"") | X4: =IFERROR((240.77+1.12)/([1]!s_stm07_bs_fininv($A4,$A$1,1,100000000)+[1]!s_stm07_bs_71($A4,$A$1,1,100000000)),"") | Y4: =(10.47+240.21)/(240.77+1.12) -> 1.0363388 | Z4: =IF([1]!b_stm07_bs(A4,74,$A$1,1,100000000)="0","",IFERROR([1]!b_stm07_bs(A4,74,$A$1,1,100000000),"")) -> 0 | AA4: =IF([1]!b_stm07_bs(A4,109,$A$1,1,100000000)="0","",IFERROR([1]!b_stm07_bs(A4,109,$A$1,1,100000000),"")) -> 0 | AB4: =IF([1]!s_stmnote_bank_5n(A4,$A$1,1)="0","",IFERROR([1]!s_stmnote_bank_5n(A4,$A$1,1),"")) -> 0 | AC4: =IF([1]!s_stmnote_bank_23n(A4,$A$1,1)=0,"",IFERROR([1]!s_stmnote_bank_23n(A4,$A$1,1),"")) | AD4: =RANK(AC4,AC$5:AC$192,1)&" "&COUNTIF(AC$5:AC$192,">0") -> #VALUE! | AE4: =IF([1]!s_stmnote_bank_capadequacyratio(A4,$A$1,1)="0","",IFERROR([1]!s_stmnote_bank_capadequacyratio(A4,$A$1,1),"")) -> 0 | AF4: =IF([1]!s_stmnote_bank_capadequacyratio_ct1(A4,$A$1,1)=0,"",IFERROR([1]!s_stmnote_bank_capadequacyratio_ct1(A4,$A$1,1),"")) | AG4: =RANK(AF4,AF$5:AF$192,0)&" "&COUNTIF(AF$5:AF$192,">0") -> #VALUE! | AH4: =IF(OR([1]!s_fa_roe(A4,20201231)=0,[1]!s_fa_roe(A4,20211231)="0",[1]!s_fa_roe(A4,20221231)="0"),"",IFERROR(([1]!s_fa_roe(A4,20221231)+[1]!s_fa_roe(A4,20201231)+[1]!s_fa_roe(A4,20211231))/3,"")) | AI4: =RANK(AH4,AH$5:AH$192,1)&" "&COUNTIF(AH$5:AH$192,">0") -> #VALUE! | AJ4: =IFERROR(([1]!s_stmnote_bank_65(A4,$A$1,1,2,4,100000000)+[1]!s_stmnote_bank_65(A4,$A$1,1,2,6,100000000))/[1]!s_stmnote_bank_1n(A4,$A$1,1,100000000),"") | AK4: =IFERROR([1]!s_stmnote_bank_614(A4,$A$1,1,2,100000000)/[1]!s_stmnote_bank_647(A4,$A$1,1,2,100000000),"") | AL4: =IFERROR(([1]!b_stm07_bs(A4,104,$A$1,1,100000000)+[1]!b_stm07_bs(A4,106,$A$1,1,100000000)+[1]!b_stm07_bs(A4,76,$A$1,1,100000000)+[1]!b_stm07_bs(A4,108,$A$1,1,100000000)+[1]!b_stm07_bs(A4,95,$A$1,1,100000000))/[1]!b_stm07_bs(A4,128,$A$1,1,100000000),"") | AM4: =IFERROR(([1]!s_stmnote_bank_614(A4,$A$1,1,2,100000000)+[1]!b_stm07_bs(A4,104,$A$1,1,100000000)+[1]!b_stm07_bs(A4,106,$A$1,1,100000000)+[1]!b_stm07_bs(A4,76,$A$1,1,100000000)+[1]!b_stm07_bs(A4,108,$A$1,1,100000000)+[1]!b_stm07_bs(A4,95,$A$1,1,100000000))/[1]!b_stm07_bs(A4,128,$A$1,1,100000000),"") | AN4: =IF(Z4>#REF!,#REF!,IF(Z4>#REF!,#REF!,IF(Z4>#REF!,#REF!,IF(Z4>#REF!,#REF!,IF(Z4>#REF!,#REF!,IF(Z4>#REF!,#REF!,IF(Z4>#REF!,#REF!,#REF!))))))) -> #REF! | AO4: =IF(AA4>#REF!,#REF!,IF(AA4>#REF!,#REF!,IF(AA4>#REF!,#REF!,IF(AA4>#REF!,#REF!,IF(AA4>#REF!,#REF!,IF(AA4>#REF!,#REF!,IF(AA4>#REF!,#REF!,#REF!))))))) -> #REF! | AP4: =IF(AB4<#REF!,#REF!,IF(AB4<#REF!,#REF!,IF(AB4<#REF!,#REF!,IF(AB4<#REF!,#REF!,IF(AB4<#REF!,#REF!,IF(AB4<#REF!,#REF!,#REF!)))))) -> #REF! | AQ4: =IF(AC4>#REF!,#REF!,IF(AC4>#REF!,#REF!,IF(AC4>#REF!,#REF!,IF(AC4>#REF!,#REF!,#REF!)))) -> #REF! | AR4: =IF(AE4>#REF!,#REF!,IF(AE4>#REF!,#REF!,IF(AE4>#REF!,#REF!,IF(AE4>#REF!,#REF!,#REF!)))) -> #REF! | AS4: =IF(AF4>#REF!,#REF!,IF(AF4>#REF!,#REF!,IF(AF4>#REF!,#REF!,IF(AF4>#REF!,#REF!,#REF!)))) -> #REF! | AT4: =IF(AH4>#REF!,#REF!,IF(AH4>#REF!,#REF!,IF(AH4>#REF!,#REF!,IF(AH4>#REF!,#REF!,IF(AH4>#REF!,#REF!,#REF!))))) -> #REF! | AU4: =AN4*$AN$3+AP4*$AP$3+AQ4*$AQ$3+AR4*$AR$3+AS4*$AS$3+AT4*$AT$3+$AO$3*AO4 -> #REF! | AV4: 强 | AW4: 较低 | AX4: 好 | AY4: =IFERROR(VLOOKUP(AV4,#REF!,3,0),"") | AZ4: =IFERROR(VLOOKUP(AW4,#REF!,3,0),"") | BA4: =IFERROR(VLOOKUP(AX4,#REF!,3,0),"") | BB4: =IFERROR(AY4*#REF!+AZ4*#REF!+BA4*#REF!,"") | BC4: =IFERROR(AU4*0.6+BB4*0.4,"") | BD4: =IFERROR(VLOOKUP(BC4*10,#REF!,2,1),"") | BH4: =[1]!b_issuer_shareholder(A4,"",1) -> 0 | BI4: =[1]!b_issuer_propofshareholder(A4,"",1) -> 0 | BJ4: =LEFT(B4,2) -> 0 | BK4: =[1]!s_info_city(A4) -> 0 | BL4: =IF([1]!s_stmnote_bank_17n(A4,$A$1,1)="0","",[1]!s_stmnote_bank_17n(A4,$A$1,1)) -> 0 | BM4: =IF([1]!s_stmnote_bank_18n(A4,$A$1,1)="0","",[1]!s_stmnote_bank_18n(A4,$A$1,1)) -> 0 | BN4: =IF([1]!s_stmnote_bank_58(A4,$A$1,1)="0","",[1]!s_stmnote_bank_58(A4,$A$1,1)) -> 0 | BO4: =IF([1]!s_stmnote_bank_60(A4,$A$1,1)="0","",[1]!s_stmnote_bank_60(A4,$A$1,1)) -> 0 | BP4: =[1]!s_stmnote_bank_5444(A4,$A$1,1) -> 0 | BQ4: =[1]!s_stmnote_bank_129n($A4,$A$1,1) -> 0 | BR4: =([1]!b_stm07_is(A4,19,$A$1,1,100000000))/AVERAGE([1]!s_stmnote_bank_35(A4,$A$1,1,100000000),[1]!s_stmnote_bank_35(A4,$E$1,1,100000000),[1]!s_stmnote_bank_35(A4,$F$1,1,100000000),[1]!s_stmnote_bank_35(A4,$G$1,1,100000000))*100 -> #DIV/0! | BT4: 10 | BU4: 70 | BV4: 5 | BW4: 10 | BX4: =100-SUM(BT4:BW4) -> 5 | BY4: =IFERROR([1]!b_stm07_is(A4,20,$A$1,1,100000000)/AVERAGEIF(CA4:CE4,">0")*100,0) -> 0 | CF4: =IF(BP4<>0,BP4,IFERROR(IF(([1]!b_stm07_is(A4,19,$A$1,1,100000000)-[1]!b_stm07_is(A4,20,$A$1,1,100000000))/AVERAGE([1]!s_stmnote_bank_35(A4,$A$1,1,100000000),[1]!s_stmnote_bank_35(A4,$B$1,1,100000000))*100=0,"",([1]!b_stm07_is(A4,19,$A$1,1,100000000)-[1]!b_stm07_is(A4,20,$A$1,1,100000000))/AVERAGE([1]!s_stmnote_bank_35(A4,$A$1,1,100000000),[1]!s_stmnote_bank_35(A4,$B$1,1,100000000))*100),"")) | CG4: =RANK(CF4,CF$5:CF$192,0)&" "&COUNTIF(CF$5:CF$192,">0") -> #VALUE! | CH4: =IFERROR(CF4/100/P4,"") | CI4: =RANK(CH4,CH$5:CH$192,0)&" "&COUNTIF(CH$5:CH$192,">0") -> #VALUE! | CJ4: =[1]!s_stmnote_bank_30(A4,$A$1,1) -> 0 | CM4: =CK4/(5/8*[1]!s_stmnote_bank_1n($A4,$A$1,1,100000000)+[1]!s_stmnote_bank_1n($A4,$B$1,1,100000000)*3/8) -> #DIV/0! | CO4: =CN4/(5/8*[1]!b_stm07_bs($A4,109,$A$1,1,100000000)+[1]!b_stm07_bs($A4,109,$B$1,1,100000000)*3/8) -> #DIV/0! | CP4: =[1]!b_stm07_bs($A4,141,$A$1,1,100000000) -> 0 | CQ4: =[1]!b_stm07_bs($A4,141,$D$1,1,100000000) -> 0 | CR4: =IF([1]!s_fa_roic_yearly($A4,$A$1)=0,"",[1]!s_fa_roic_yearly($A4,$A$1)) | CS4: =RANK(CR4,CR$5:CR$192,1)&" "&COUNTIF(CR$5:CR$192,">0") -> #VALUE! | CT4: =IF([1]!s_fa_roic_yearly($A4,$D$1)=0,"",[1]!s_fa_roic_yearly($A4,$D$1)) | CU4: =RANK(CT4,CT$5:CT$192,1)&" "&COUNTIF(CT$5:CT$192,">0") -> #VALUE! | CV4: =[1]!s_stm07_bs(A4,"W14578191",$A$1,1,100000000) -> 0 | CW4: =[1]!s_stmnote_bank_682($A4,$A$1,1,2,100000000) -> 0 | CX4: =IF(CW4*CV4=0,"",CW4/CV4)
A5: 111885082.IB | B5: 大连农村商业银行股份有限公司 | C5: 大连农商行 | D5: 农商行 | F5: AA- | J5: =VLOOKUP(B5,[3]额度信息!$B:$T,19,0) -> #N/A | L5: =IFERROR(([1]!b_stm07_bs($A5,47,$A$1,1,100000000))/[1]!b_stm07_bs($A5,109,$A$1,1,100000000),"") -> 0.093121223 | O5: =RANK(N5,N$5:N$192,1)&" "&COUNTIF(N$5:N$192,">0") -> #N/A | P5: =IF(IFERROR(R5+AB5/100,"")=0,"",IFERROR(R5+AB5/100,"")) -> 0.0424 | Q5: =RANK(P5,P$5:P$192,1)&" "&COUNTIF(P$5:P$192,">0") -> 121 169 | R5: =IFERROR([1]!s_stmnote_bank($A5,"34",$A$1,100000000)/[1]!s_stmnote_bank_1n(A5,$A$1,1,100000000),"") -> 0 | Z5: =[1]!b_stm07_bs(A5,74,$A$1,1,100000000) -> 1280.9931 | AA5: =[1]!b_stm07_bs(A5,109,$A$1,1,100000000) -> 1131.2467 | AB5: =[1]!s_stmnote_bank_5n(A5,$A$1,1) -> 4.24 | AC5: =IF([1]!s_stmnote_bank_23n(A5,$A$1,1)=0,"",IFERROR([1]!s_stmnote_bank_23n(A5,$A$1,1),"")) | AD5: =RANK(AC5,AC$5:AC$192,1)&" "&COUNTIF(AC$5:AC$192,">0") -> #VALUE! | AE5: =[1]!s_stmnote_bank_capadequacyratio(A5,$A$1,1) -> 0 | AF5: =IF([1]!s_stmnote_bank_capadequacyratio_ct1(A5,$A$1,1)=0,"",IFERROR([1]!s_stmnote_bank_capadequacyratio_ct1(A5,$A$1,1),"")) | AG5: =RANK(AF5,AF$5:AF$192,1)&" "&COUNTIF(AF$5:AF$192,">0") -> #VALUE! | AH5: =IF(OR([1]!s_fa_roe(A5,20201231)=0,[1]!s_fa_roe(A5,20211231)="0",[1]!s_fa_roe(A5,20221231)="0"),"",IFERROR(([1]!s_fa_roe(A5,20221231)+[1]!s_fa_roe(A5,20201231)+[1]!s_fa_roe(A5,20211231))/3,"")) -> 0.6798 | AI5: =RANK(AH5,AH$5:AH$192,1)&" "&COUNTIF(AH$5:AH$192,">0") -> 4 173 | AJ5: =IFERROR(([1]!s_stmnote_bank_65(A5,$A$1,1,2,4,100000000)+[1]!s_stmnote_bank_65(A5,$A$1,1,2,6,100000000))/[1]!s_stmnote_bank_1n(A5,$A$1,1,100000000),"") -> 0.23258203 | AK5: =IFERROR([1]!s_stmnote_bank_614(A5,$A$1,1,2,100000000)/[1]!s_stmnote_bank_647(A5,$A$1,1,2,100000000),"") -> 0 | AL5: =IFERROR(([1]!b_stm07_bs(A5,104,$A$1,1,100000000)+[1]!b_stm07_bs(A5,106,$A$1,1,100000000)+[1]!b_stm07_bs(A5,76,$A$1,1,100000000)+[1]!b_stm07_bs(A5,108,$A$1,1,100000000)+[1]!b_stm07_bs(A5,95,$A$1,1,100000000))/[1]!b_stm07_bs(A5,128,$A$1,1,100000000),"") -> 0.037966512 | AM5: =IFERROR(([1]!s_stmnote_bank_614(A5,$A$1,1,2,100000000)+[1]!b_stm07_bs(A5,104,$A$1,1,100000000)+[1]!b_stm07_bs(A5,106,$A$1,1,100000000)+[1]!b_stm07_bs(A5,76,$A$1,1,100000000)+[1]!b_stm07_bs(A5,108,$A$1,1,100000000)+[1]!b_stm07_bs(A5,95,$A$1,1,100000000))/[1]!b_stm07_bs(A5,128,$A$1,1,100000000),"") -> 0.037966512 | AN5: =IF(Z5>#REF!,#REF!,IF(Z5>#REF!,#REF!,IF(Z5>#REF!,#REF!,IF(Z5>#REF!,#REF!,IF(Z5>#REF!,#REF!,IF(Z5>#REF!,#REF!,IF(Z5>#REF!,#REF!,#REF!))))))) -> #REF! | AO5: =IF(AA5>#REF!,#REF!,IF(AA5>#REF!,#REF!,IF(AA5>#REF!,#REF!,IF(AA5>#REF!,#REF!,IF(AA5>#REF!,#REF!,IF(AA5>#REF!,#REF!,IF(AA5>#REF!,#REF!,#REF!))))))) -> #REF! | AP5: =IF(AB5<#REF!,#REF!,IF(AB5<#REF!,#REF!,IF(AB5<#REF!,#REF!,IF(AB5<#REF!,#REF!,IF(AB5<#REF!,#REF!,IF(AB5<#REF!,#REF!,#REF!)))))) -> #REF! | AQ5: =IF(AC5>#REF!,#REF!,IF(AC5>#REF!,#REF!,IF(AC5>#REF!,#REF!,IF(AC5>#REF!,#REF!,#REF!)))) -> #REF! | AR5: =IF(AE5>#REF!,#REF!,IF(AE5>#REF!,#REF!,IF(AE5>#REF!,#REF!,IF(AE5>#REF!,#REF!,#REF!)))) -> #REF! | AS5: =IF(AF5>#REF!,#REF!,IF(AF5>#REF!,#REF!,IF(AF5>#REF!,#REF!,IF(AF5>#REF!,#REF!,#REF!)))) -> #REF! | AT5: =IF(AH5>#REF!,#REF!,IF(AH5>#REF!,#REF!,IF(AH5>#REF!,#REF!,IF(AH5>#REF!,#REF!,IF(AH5>#REF!,#REF!,#REF!))))) -> #REF! | AU5: =AN5*$AN$3+AP5*$AP$3+AQ5*$AQ$3+AR5*$AR$3+AS5*$AS$3+AT5*$AT$3+$AO$3*AO5 -> #REF! | AY5: =IFERROR(VLOOKUP(AV5,#REF!,3,0),"") | AZ5: =IFERROR(VLOOKUP(AW5,#REF!,3,0),"") | BA5: =IFERROR(VLOOKUP(AX5,#REF!,3,0),"") | BB5: =IFERROR(AY5*#REF!+AZ5*#REF!+BA5*#REF!,"") | BC5: =IFERROR(AU5*0.6+BB5*0.4,"") | BD5: =IFERROR(VLOOKUP(BC5*10,#REF!,2,1),"") | BH5: 大连德泰控股有限公司 | BI5: 10 | BJ5: 辽宁 | BK5: 大连市 | BL5: =IF([1]!s_stmnote_bank_17n(A5,$A$1,1)="0","",[1]!s_stmnote_bank_17n(A5,$A$1,1)) -> 0 | BM5: =IF([1]!s_stmnote_bank_18n(A5,$A$1,1)="0","",[1]!s_stmnote_bank_18n(A5,$A$1,1)) -> 0 | BP5: =[1]!s_stmnote_bank_5444(A5,$A$1,1) -> 0 | BQ5: =[1]!s_stmnote_bank_129n($A5,$A$1,1) -> 60.6565 | BR5: =IFERROR(BS5/SUMPRODUCT(BT5:BX5,$BT$4:$BX$4)*SUMIFS($BT$4:$BX$4,BT5:BX5,">0")*100,0) -> 4.3579095 | BS5: =[1]!b_stm07_is(A5,19,$A$1,1,100000000) -> 49.784056 | BT5: =[1]!s_stm07_bs(A5,"W15273164",$A$1,1,100000000)-[1]!s_stm07_bs(A5,"W17642530",$A$1,1,100000000)-[1]!s_stm07_bs(A5,"W15910877",$A$1,1,100000000)-[1]!s_stm07_bs_39(A5,$A$1,1,100000000)-[1]!s_stm07_bs(A5,"W17700468",$A$1,1,100000000)-[1]!s_stm07_bs(A5,"W16504296",$A$1,1,100000000)-[1]!s_stm07_bs(A5,"W13769069",$A$1,1,100000000) -> 1207.8577 | BU5: =[1]!s_stm07_bs(A5,"W15273164",$B$1,1,100000000)-[1]!s_stm07_bs(A5,"W17642530",$B$1,1,100000000)-[1]!s_stm07_bs(A5,"W15910877",$B$1,1,100000000)-[1]!s_stm07_bs_39(A5,$B$1,1,100000000)-[1]!s_stm07_bs(A5,"W17700468",$B$1,1,100000000)-[1]!s_stm07_bs(A5,"W16504296",$B$1,1,100000000)-[1]!s_stm07_bs(A5,"W13769069",$B$1,1,100000000) -> 1114.455 | BV5: =[1]!s_stm07_bs(A5,"W15273164",$E$1,1,100000000)-[1]!s_stm07_bs(A5,"W17642530",$E$1,1,100000000)-[1]!s_stm07_bs(A5,"W15910877",$E$1,1,100000000)-[1]!s_stm07_bs_39(A5,$E$1,1,100000000)-[1]!s_stm07_bs(A5,"W17700468",$E$1,1,100000000)-[1]!s_stm07_bs(A5,"W16504296",$E$1,1,100000000)-[1]!s_stm07_bs(A5,"W13769069",$E$1,1,100000000) -> 1216.4244 | BW5: =[1]!s_stm07_bs(A5,"W15273164",$F$1,1,100000000)-[1]!s_stm07_bs(A5,"W17642530",$F$1,1,100000000)-[1]!s_stm07_bs(A5,"W15910877",$F$1,1,100000000)-[1]!s_stm07_bs_39(A5,$F$1,1,100000000)-[1]!s_stm07_bs(A5,"W17700468",$F$1,1,100000000)-[1]!s_stm07_bs(A5,"W16504296",$F$1,1,100000000)-[1]!s_stm07_bs(A5,"W13769069",$F$1,1,100000000) -> 1202.1681 | BX5: =[1]!s_stm07_bs(A5,"W15273164",$G$1,1,100000000)-[1]!s_stm07_bs(A5,"W17642530",$G$1,1,100000000)-[1]!s_stm07_bs(A5,"W15910877",$G$1,1,100000000)-[1]!s_stm07_bs_39(A5,$G$1,1,100000000)-[1]!s_stm07_bs(A5,"W17700468",$G$1,1,100000000)-[1]!s_stm07_bs(A5,"W16504296",$G$1,1,100000000)-[1]!s_stm07_bs(A5,"W13769069",$G$1,1,100000000) -> 1208.8324 | BY5: =IFERROR([1]!b_stm07_is(A5,20,$A$1,1,100000000)/AVERAGEIF(CA5:CE5,">0")*100,0) -> 3.0994077 | BZ5: =[1]!b_stm07_is(A5,20,$A$1,1,100000000) -> 35.461784 | CA5: =[1]!s_stmnote_bank_38(A5,$A$1,1,100000000) -> 1191.5108 | CB5: =[1]!s_stmnote_bank_38(A5,$B$1,1,100000000) -> 1049.9961 | CC5: =[1]!s_stmnote_bank_38(A5,$E$1,1,100000000) -> 1189.5793 | CD5: =[1]!s_stmnote_bank_38(A5,$F$1,1,100000000) -> 1176.328 | CE5: =[1]!s_stmnote_bank_38(A5,$G$1,1,100000000) -> 1113.3216 | CF5: =IF(BP5<>0,BP5,IFERROR(IF(([1]!b_stm07_is(A5,19,$A$1,1,100000000)-[1]!b_stm07_is(A5,20,$A$1,1,100000000))/AVERAGE([1]!s_stmnote_bank_35(A5,$A$1,1,100000000),[1]!s_stmnote_bank_35(A5,$B$1,1,100000000))*100=0,"",([1]!b_stm07_is(A5,19,$A$1,1,100000000)-[1]!b_stm07_is(A5,20,$A$1,1,100000000))/AVERAGE([1]!s_stmnote_bank_35(A5,$A$1,1,100000000),[1]!s_stmnote_bank_35(A5,$B$1,1,100000000))*100),"")) -> 1.284989 | CG5: =RANK(CF5,CF$5:CF$192,0)&" "&COUNTIF(CF$5:CF$192,">0") -> 162 171 | CH5: =IFERROR(CF5/100/P5,"") -> 0.30306343 | CI5: =RANK(CH5,CH$5:CH$192,0)&" "&COUNTIF(CH$5:CH$192,">0") -> 143 169 | CJ5: =[1]!s_stmnote_bank_30(A5,$A$1,1) -> 31.1487 | CP5: =[1]!b_stm07_bs($A5,141,$A$1,1,100000000) -> 82.638154 | CQ5: =[1]!b_stm07_bs($A5,141,$D$1,1,100000000) -> 85.94281 | CR5: =IF([1]!s_fa_roic_yearly($A5,$A$1)=0,"",[1]!s_fa_roic_yearly($A5,$A$1)) -> 0.7435 | CS5: =RANK(CR5,CR$5:CR$192,0)/COUNTIF(CR$5:CR$192,">0") -> 0.9704142 | CT5: =IF([1]!s_fa_roic_yearly($A5,$D$1)=0,"",[1]!s_fa_roic_yearly($A5,$D$1)) -> 1.4688 | CU5: =RANK(CT5,CT$5:CT$192,0)/COUNTIF(CT$5:CT$192,">0") -> 0.98591549 | CV5: =[1]!s_stm07_bs(A5,"W14578191",$A$1,1,100000000) -> 679.82747 | CW5: =[1]!s_stmnote_bank_682($A5,$A$1,1,2,100000000) -> 0 | CX5: =IF(CW5*CV5=0,"",CW5/CV5)
A6: 112392890.IB | B6: 法国巴黎银行(中国)有限公司 | C6: 法国巴黎银行(中国) | D6: 外资行 | E6: 有 | F6: AAA | H6: B+ | J6: =VLOOKUP(B6,[3]额度信息!$B:$T,19,0) -> #N/A | K6: 业务以中间业务为主，获得母行法巴较多资源支持，客户也以集团为主，协同性很强；信贷业务占比小、服务集团关联客户为主，风险暴露少；盈利虽然偏低，但资本、流动性安全垫很高;高度依赖同业资金，降2级；集团支持提1级 | L6: =IFERROR(([1]!b_stm07_bs($A6,47,$A$1,1,100000000))/[1]!b_stm07_bs($A6,109,$A$1,1,100000000),"") -> 0.19592606 | O6: =RANK(N6,N$5:N$192,1)&" "&COUNTIF(N$5:N$192,">0") -> #N/A | P6: =IF(IFERROR(R6+AB6/100,"")=0,"",IFERROR(R6+AB6/100,"")) -> 0.0052975703 | Q6: =RANK(P6,P$5:P$192,1)&" "&COUNTIF(P$5:P$192,">0") -> 1 169 | R6: =IFERROR([1]!s_stmnote_bank($A6,"34",$A$1,100000000)/[1]!s_stmnote_bank_1n(A6,$A$1,1,100000000),"") -> 0.0023975703 | Z6: =[1]!b_stm07_bs(A6,74,$A$1,1,100000000) -> 645.1722 | AA6: =[1]!b_stm07_bs(A6,109,$A$1,1,100000000) -> 266.42332 | AB6: =[1]!s_stmnote_bank_5n(A6,$A$1,1) -> 0.29 | AC6: =IF([1]!s_stmnote_bank_23n(A6,$A$1,1)=0,"",IFERROR([1]!s_stmnote_bank_23n(A6,$A$1,1),"")) -> 1076.23 | AD6: =RANK(AC6,AC$5:AC$192,1)&" "&COUNTIF(AC$5:AC$192,">0") -> 166 167 | AE6: =[1]!s_stmnote_bank_capadequacyratio(A6,$A$1,1) -> 16.6 | AF6: =IF([1]!s_stmnote_bank_capadequacyratio_ct1(A6,$A$1,1)=0,"",IFERROR([1]!s_stmnote_bank_capadequacyratio_ct1(A6,$A$1,1),"")) -> 16 | AG6: =RANK(AF6,AF$5:AF$192,1)&" "&COUNTIF(AF$5:AF$192,">0") -> 159 167 | AH6: =IF(OR([1]!s_fa_roe(A6,20201231)=0,[1]!s_fa_roe(A6,20211231)="0",[1]!s_fa_roe(A6,20221231)="0"),"",IFERROR(([1]!s_fa_roe(A6,20221231)+[1]!s_fa_roe(A6,20201231)+[1]!s_fa_roe(A6,20211231))/3,"")) -> 2.9750667 | AI6: =RANK(AH6,AH$5:AH$192,1)&" "&COUNTIF(AH$5:AH$192,">0") -> 17 173 | AJ6: =IFERROR(([1]!s_stmnote_bank_65(A6,$A$1,1,2,4,100000000)+[1]!s_stmnote_bank_65(A6,$A$1,1,2,6,100000000))/[1]!s_stmnote_bank_1n(A6,$A$1,1,100000000),"") -> 0.039835042 | AK6: =IFERROR([1]!s_stmnote_bank_614(A6,$A$1,1,2,100000000)/[1]!s_stmnote_bank_647(A6,$A$1,1,2,100000000),"") -> 0.3717991 | AL6: =IFERROR(([1]!b_stm07_bs(A6,104,$A$1,1,100000000)+[1]!b_stm07_bs(A6,106,$A$1,1,100000000)+[1]!b_stm07_bs(A6,76,$A$1,1,100000000)+[1]!b_stm07_bs(A6,108,$A$1,1,100000000)+[1]!b_stm07_bs(A6,95,$A$1,1,100000000))/[1]!b_stm07_bs(A6,128,$A$1,1,100000000),"") -> 0.3048583 | AM6: =IFERROR(([1]!s_stmnote_bank_614(A6,$A$1,1,2,100000000)+[1]!b_stm07_bs(A6,104,$A$1,1,100000000)+[1]!b_stm07_bs(A6,106,$A$1,1,100000000)+[1]!b_stm07_bs(A6,76,$A$1,1,100000000)+[1]!b_stm07_bs(A6,108,$A$1,1,100000000)+[1]!b_stm07_bs(A6,95,$A$1,1,100000000))/[1]!b_stm07_bs(A6,128,$A$1,1,100000000),"") -> 0.48807651 | AN6: =IF(Z6>#REF!,#REF!,IF(Z6>#REF!,#REF!,IF(Z6>#REF!,#REF!,IF(Z6>#REF!,#REF!,IF(Z6>#REF!,#REF!,IF(Z6>#REF!,#REF!,IF(Z6>#REF!,#REF!,#REF!))))))) -> #REF! | AO6: =IF(AA6>#REF!,#REF!,IF(AA6>#REF!,#REF!,IF(AA6>#REF!,#REF!,IF(AA6>#REF!,#REF!,IF(AA6>#REF!,#REF!,IF(AA6>#REF!,#REF!,IF(AA6>#REF!,#REF!,#REF!))))))) -> #REF! | AP6: =IF(AB6<#REF!,#REF!,IF(AB6<#REF!,#REF!,IF(AB6<#REF!,#REF!,IF(AB6<#REF!,#REF!,IF(AB6<#REF!,#REF!,IF(AB6<#REF!,#REF!,#REF!)))))) -> #REF! | AQ6: =IF(AC6>#REF!,#REF!,IF(AC6>#REF!,#REF!,IF(AC6>#REF!,#REF!,IF(AC6>#REF!,#REF!,#REF!)))) -> #REF! | AR6: =IF(AE6>#REF!,#REF!,IF(AE6>#REF!,#REF!,IF(AE6>#REF!,#REF!,IF(AE6>#REF!,#REF!,#REF!)))) -> #REF! | AS6: =IF(AF6>#REF!,#REF!,IF(AF6>#REF!,#REF!,IF(AF6>#REF!,#REF!,IF(AF6>#REF!,#REF!,#REF!)))) -> #REF! | AT6: =IF(AH6>#REF!,#REF!,IF(AH6>#REF!,#REF!,IF(AH6>#REF!,#REF!,IF(AH6>#REF!,#REF!,IF(AH6>#REF!,#REF!,#REF!))))) -> #REF! | AU6: =AN6*$AN$3+AP6*$AP$3+AQ6*$AQ$3+AR6*$AR$3+AS6*$AS$3+AT6*$AT$3+$AO$3*AO6 -> #REF! | AV6: 强 | AW6: 低 | AX6: 好 | AY6: =IFERROR(VLOOKUP(AV6,#REF!,3,0),"") | AZ6: =IFERROR(VLOOKUP(AW6,#REF!,3,0),"") | BA6: =IFERROR(VLOOKUP(AX6,#REF!,3,0),"") | BB6: =IFERROR(AY6*#REF!+AZ6*#REF!+BA6*#REF!,"") | BC6: =IFERROR(AU6*0.6+BB6*0.4,"") | BD6: =IFERROR(VLOOKUP(BC6*10,#REF!,2,1),"") | BE6: 2 | BF6: -1 | BG6: 负债不稳-1 | BL6: =IF([1]!s_stmnote_bank_17n(A6,$A$1,1)="0","",[1]!s_stmnote_bank_17n(A6,$A$1,1)) -> 0 | BM6: =IF([1]!s_stmnote_bank_18n(A6,$A$1,1)="0","",[1]!s_stmnote_bank_18n(A6,$A$1,1)) -> 0 | BP6: =[1]!s_stmnote_bank_5444(A6,$A$1,1) -> 0 | BQ6: =[1]!s_stmnote_bank_129n($A6,$A$1,1) -> 78.8717 | BR6: =IFERROR(BS6/SUMPRODUCT(BT6:BX6,$BT$4:$BX$4)*SUMIFS($BT$4:$BX$4,BT6:BX6,">0")*100,0) -> 1.9205411 | BS6: =[1]!b_stm07_is(A6,19,$A$1,1,100000000) -> 13.085051 | BT6: =[1]!s_stm07_bs(A6,"W15273164",$A$1,1,100000000)-[1]!s_stm07_bs(A6,"W17642530",$A$1,1,100000000)-[1]!s_stm07_bs(A6,"W15910877",$A$1,1,100000000)-[1]!s_stm07_bs_39(A6,$A$1,1,100000000)-[1]!s_stm07_bs(A6,"W17700468",$A$1,1,100000000)-[1]!s_stm07_bs(A6,"W16504296",$A$1,1,100000000)-[1]!s_stm07_bs(A6,"W13769069",$A$1,1,100000000) -> 620.62995 | BU6: =[1]!s_stm07_bs(A6,"W15273164",$B$1,1,100000000)-[1]!s_stm07_bs(A6,"W17642530",$B$1,1,100000000)-[1]!s_stm07_bs(A6,"W15910877",$B$1,1,100000000)-[1]!s_stm07_bs_39(A6,$B$1,1,100000000)-[1]!s_stm07_bs(A6,"W17700468",$B$1,1,100000000)-[1]!s_stm07_bs(A6,"W16504296",$B$1,1,100000000)-[1]!s_stm07_bs(A6,"W13769069",$B$1,1,100000000) -> 691.46867 | BV6: =[1]!s_stm07_bs(A6,"W15273164",$E$1,1,100000000)-[1]!s_stm07_bs(A6,"W17642530",$E$1,1,100000000)-[1]!s_stm07_bs(A6,"W15910877",$E$1,1,100000000)-[1]!s_stm07_bs_39(A6,$E$1,1,100000000)-[1]!s_stm07_bs(A6,"W17700468",$E$1,1,100000000)-[1]!s_stm07_bs(A6,"W16504296",$E$1,1,100000000)-[1]!s_stm07_bs(A6,"W13769069",$E$1,1,100000000) -> 660.6366 | BW6: =[1]!s_stm07_bs(A6,"W15273164",$F$1,1,100000000)-[1]!s_stm07_bs(A6,"W17642530",$F$1,1,100000000)-[1]!s_stm07_bs(A6,"W15910877",$F$1,1,100000000)-[1]!s_stm07_bs_39(A6,$F$1,1,100000000)-[1]!s_stm07_bs(A6,"W17700468",$F$1,1,100000000)-[1]!s_stm07_bs(A6,"W16504296",$F$1,1,100000000)-[1]!s_stm07_bs(A6,"W13769069",$F$1,1,100000000) -> 0 | BX6: =[1]!s_stm07_bs(A6,"W15273164",$G$1,1,100000000)-[1]!s_stm07_bs(A6,"W17642530",$G$1,1,100000000)-[1]!s_stm07_bs(A6,"W15910877",$G$1,1,100000000)-[1]!s_stm07_bs_39(A6,$G$1,1,100000000)-[1]!s_stm07_bs(A6,"W17700468",$G$1,1,100000000)-[1]!s_stm07_bs(A6,"W16504296",$G$1,1,100000000)-[1]!s_stm07_bs(A6,"W13769069",$G$1,1,100000000) -> 0 | BY6: =IFERROR([1]!b_stm07_is(A6,20,$A$1,1,100000000)/AVERAGEIF(CA6:CE6,">0")*100,0) -> 1.8172822 | BZ6: =[1]!b_stm07_is(A6,20,$A$1,1,100000000) -> 7.8186414 | CA6: =[1]!s_stmnote_bank_38(A6,$A$1,1,100000000) -> 431.24335 | CB6: =[1]!s_stmnote_bank_38(A6,$B$1,1,100000000) -> 429.23295 | CC6: =[1]!s_stmnote_bank_38(A6,$E$1,1,100000000) -> 0 | CD6: =[1]!s_stmnote_bank_38(A6,$F$1,1,100000000) -> 0 | CE6: =[1]!s_stmnote_bank_38(A6,$G$1,1,100000000) -> 0 | CF6: =IF(BP6<>0,BP6,IFERROR(IF(([1]!b_stm07_is(A6,19,$A$1,1,100000000)-[1]!b_stm07_is(A6,20,$A$1,1,100000000))/AVERAGE([1]!s_stmnote_bank_35(A6,$A$1,1,100000000),[1]!s_stmnote_bank_35(A6,$B$1,1,100000000))*100=0,"",([1]!b_stm07_is(A6,19,$A$1,1,100000000)-[1]!b_stm07_is(A6,20,$A$1,1,100000000))/AVERAGE([1]!s_stmnote_bank_35(A6,$A$1,1,100000000),[1]!s_stmnote_bank_35(A6,$B$1,1,100000000))*100),"")) -> 1.0146216 | CG6: =RANK(CF6,CF$5:CF$192,0)&" "&COUNTIF(CF$5:CF$192,">0") -> 169 171 | CH6: =IFERROR(CF6/100/P6,"") -> 1.9152584 | CI6: =RANK(CH6,CH$5:CH$192,0)&" "&COUNTIF(CH$5:CH$192,">0") -> 12 169 | CJ6: =[1]!s_stmnote_bank_30(A6,$A$1,1) -> 52.3122 | CP6: =[1]!b_stm07_bs($A6,141,$A$1,1,100000000) -> 104.52749 | CQ6: =[1]!b_stm07_bs($A6,141,$D$1,1,100000000) -> 108.7685 | CR6: =IF([1]!s_fa_roic_yearly($A6,$A$1)=0,"",[1]!s_fa_roic_yearly($A6,$A$1)) -> 2.159 | CS6: =RANK(CR6,CR$5:CR$192,0)/COUNTIF(CR$5:CR$192,">0") -> 0.9408284 | CT6: =IF([1]!s_fa_roic_yearly($A6,$D$1)=0,"",[1]!s_fa_roic_yearly($A6,$D$1)) -> 8.1698 | CU6: =RANK(CT6,CT$5:CT$192,0)/COUNTIF(CT$5:CT$192,">0") -> 0.6971831 | CV6: =[1]!s_stm07_bs(A6,"W14578191",$A$1,1,100000000) -> 139.17603 | CW6: =[1]!s_stmnote_bank_682($A6,$A$1,1,2,100000000) -> 0 | CX6: =IF(CW6*CV6=0,"",CW6/CV6)
